<?xml version='1.0' encoding='UTF-8'?>
<robot name="AR5-5_08L-W4C4A6-ZY2_with_suction_cup">
  <material name="black">
    <color rgba="0.0 0.0 0.0 1.0" />
  </material>
  <material name="blue">
    <color rgba="0.0 0.0 0.8 1.0" />
  </material>
  <material name="green">
    <color rgba="0.0 0.8 0.0 1.0" />
  </material>
  <material name="grey">
    <color rgba="0.2 0.2 0.2 1.0" />
  </material>
  <material name="orange">
    <color rgba="1.0 0.423529411765 0.0392156862745 1.0" />
  </material>
  <material name="brown">
    <color rgba="0.870588235294 0.811764705882 0.764705882353 1.0" />
  </material>
  <material name="red">
    <color rgba="0.8 0.0 0.0 1.0" />
  </material>
  <material name="white">
    <color rgba="1.0 1.0 1.0 1.0" />
  </material>
  <material name="Beige">
    <color rgba="1.0 0.784 0.5765 1.0" />
  </material>
  <link name="world" />
  <joint name="fixed" type="fixed">
    <parent link="world" />
    <child link="AR5-5_08L-W4C4A6-ZY2_base" />
  </joint>
  <link name="AR5-5_08L-W4C4A6-ZY2_base">
    <visual>
      <geometry>
        <mesh filename="../meshes/AR5-5_08L-W4C4A6-ZY2_base.stl" scale="0.001 0.001 0.001" />
      </geometry>
      <origin rpy="0 0 0" xyz="0.0 0.0 0.0" />
      <material name="white" />
    </visual>
    <collision>
      <geometry>
        <mesh filename="../meshes/AR5-5_08L-W4C4A6-ZY2_base.stl" scale="0.001 0.001 0.001" />
      </geometry>
      <origin rpy="0 0 0" xyz="0.0 0.0 0.0" />
    </collision>
  </link>
  <joint name="AR5-5_08L-W4C4A6-ZY2_joint_1" type="revolute">
    <parent link="AR5-5_08L-W4C4A6-ZY2_base" />
    <child link="AR5-5_08L-W4C4A6-ZY2_link1" />
    <limit effort="108" lower="-3.1067" upper="3.1067" velocity="3.0543261909900763" />
    <axis xyz="0 0 1" />
    <origin rpy="0 0 0" xyz="0.0 0.0 0.0" />
  </joint>
  <transmission name="tran1">
    <type>transmission_interface/SimpleTransmission</type>
    <joint name="AR5-5_08L-W4C4A6-ZY2_joint_1">
      <hardwareInterface>EffortJointInterface</hardwareInterface>
    </joint>
    <actuator name="motor1">
      <hardwareInterface>EffortJointInterface</hardwareInterface>
      <mechanicalReduction>1</mechanicalReduction>
    </actuator>
  </transmission>
  <link name="AR5-5_08L-W4C4A6-ZY2_link1">
    <visual>
      <geometry>
        <mesh filename="../meshes/AR5-5_08L-W4C4A6-ZY2_link1.stl" scale="0.001 0.001 0.001" />
      </geometry>
      <origin rpy="0 0 0" xyz="0 0 0" />
      <material name="white" />
    </visual>
    <inertial>
      <mass value="2.166" />
      <inertia ixx="0.00332249" ixy="0.00000032" ixz="-0.00000048" iyy="0.00260904" iyz="-0.00001486" izz="0.00317691" />
      <origin rpy="0 0 0" xyz="-0.000184 0.0015680000000000002 0.172804" />
    </inertial>
    <collision>
      <geometry>
        <mesh filename="../meshes/AR5-5_08L-W4C4A6-ZY2_link1.stl" scale="0.001 0.001 0.001" />
      </geometry>
      <origin rpy="0 0 0" xyz="0 0 0" />
    </collision>
  </link>
  <joint name="AR5-5_08L-W4C4A6-ZY2_joint_2" type="revolute">
    <parent link="AR5-5_08L-W4C4A6-ZY2_link1" />
    <child link="AR5-5_08L-W4C4A6-ZY2_link2" />
    <limit effort="108" lower="-2.0944" upper="2.0944" velocity="3.0543261909900763" />
    <axis xyz="0 1 0" />
    <origin rpy="0 0 0" xyz="0.0 0.0 0.1745" />
  </joint>
  <transmission name="tran2">
    <type>transmission_interface/SimpleTransmission</type>
    <joint name="AR5-5_08L-W4C4A6-ZY2_joint_2">
      <hardwareInterface>EffortJointInterface</hardwareInterface>
    </joint>
    <actuator name="motor2">
      <hardwareInterface>EffortJointInterface</hardwareInterface>
      <mechanicalReduction>1</mechanicalReduction>
    </actuator>
  </transmission>
  <link name="AR5-5_08L-W4C4A6-ZY2_link2">
    <visual>
      <geometry>
        <mesh filename="../meshes/AR5-5_08L-W4C4A6-ZY2_link2.stl" scale="0.001 0.001 0.001" />
      </geometry>
      <origin rpy="0 0 0" xyz="0 0 0.0" />
      <material name="white" />
    </visual>
    <inertial>
      <mass value="1.903" />
      <inertia ixx="0.00779803" ixy="0.00000248" ixz="-0.00000226" iyy="0.00674819" iyz="-0.00049283" izz="0.00305507" />
      <origin rpy="0 0 0" xyz="-1.7e-05 0.001795 0.10668899999999999" />
    </inertial>
    <collision>
      <geometry>
        <mesh filename="../meshes/AR5-5_08L-W4C4A6-ZY2_link2.stl" scale="0.001 0.001 0.001" />
      </geometry>
      <origin rpy="0 0 0" xyz="0 0 0.0" />
    </collision>
  </link>
  <joint name="AR5-5_08L-W4C4A6-ZY2_joint_3" type="revolute">
    <parent link="AR5-5_08L-W4C4A6-ZY2_link2" />
    <child link="AR5-5_08L-W4C4A6-ZY2_link3" />
    <limit effort="66" lower="-3.1067" upper="3.1067" velocity="4.71238898038469" />
    <axis xyz="0 0 1" />
    <origin rpy="0 0 0" xyz="0.0 0.0 0.332" />
  </joint>
  <transmission name="tran3">
    <type>transmission_interface/SimpleTransmission</type>
    <joint name="AR5-5_08L-W4C4A6-ZY2_joint_3">
      <hardwareInterface>EffortJointInterface</hardwareInterface>
    </joint>
    <actuator name="motor3">
      <hardwareInterface>EffortJointInterface</hardwareInterface>
      <mechanicalReduction>1</mechanicalReduction>
    </actuator>
  </transmission>
  <link name="AR5-5_08L-W4C4A6-ZY2_link3">
    <visual>
      <geometry>
        <mesh filename="../meshes/AR5-5_08L-W4C4A6-ZY2_link3.stl" scale="0.001 0.001 0.001" />
      </geometry>
      <origin rpy="0 0 0" xyz="0 0 0" />
      <material name="white" />
    </visual>
    <inertial>
      <mass value="1.845" />
      <inertia ixx="0.00641285" ixy="0.00000909" ixz="0.00034765" iyy="0.00591595" iyz="-0.00002314" izz="0.00276583" />
      <origin rpy="0 0 0" xyz="0.008227 -0.0012729999999999998 -0.020611" />
    </inertial>
    <collision>
      <geometry>
        <mesh filename="../meshes/AR5-5_08L-W4C4A6-ZY2_link3.stl" scale="0.001 0.001 0.001" />
      </geometry>
      <origin rpy="0 0 0" xyz="0 0 0" />
    </collision>
  </link>
  <joint name="AR5-5_08L-W4C4A6-ZY2_joint_4" type="revolute">
    <parent link="AR5-5_08L-W4C4A6-ZY2_link3" />
    <child link="AR5-5_08L-W4C4A6-ZY2_link4" />
    <limit effort="66" lower="-1.0472" upper="2.5307" velocity="5.235987755982989" />
    <axis xyz="0 1 0" />
    <origin rpy="0 0 0" xyz="0.0105 0.0 0.0" />
  </joint>
  <transmission name="tran4">
    <type>transmission_interface/SimpleTransmission</type>
    <joint name="AR5-5_08L-W4C4A6-ZY2_joint_4">
      <hardwareInterface>EffortJointInterface</hardwareInterface>
    </joint>
    <actuator name="motor4">
      <hardwareInterface>EffortJointInterface</hardwareInterface>
      <mechanicalReduction>1</mechanicalReduction>
    </actuator>
  </transmission>
  <link name="AR5-5_08L-W4C4A6-ZY2_link4">
    <visual>
      <geometry>
        <mesh filename="../meshes/AR5-5_08L-W4C4A6-ZY2_link4.stl" scale=".001 0.001 0.001" />
      </geometry>
      <origin rpy="0 0 0" xyz="0.0 0.0 0.0" />
      <material name="white" />
    </visual>
    <inertial>
      <mass value="1.037" />
      <inertia ixx="0.00294639" ixy="-0.00002418" ixz="-0.00012203" iyy="0.00244447" iyz="0.00022029" izz="0.00140961" />
      <origin rpy="0 0 0" xyz="-0.009242 -0.0021720000000000003 0.084042" />
    </inertial>
    <collision>
      <geometry>
        <mesh filename="../meshes/AR5-5_08L-W4C4A6-ZY2_link4.stl" scale="0.001 0.001 0.001" />
      </geometry>
      <origin rpy="0 0 0" xyz="0.0 0.0 0.0" />
    </collision>
  </link>
  <joint name="AR5-5_08L-W4C4A6-ZY2_joint_5" type="revolute">
    <parent link="AR5-5_08L-W4C4A6-ZY2_link4" />
    <child link="AR5-5_08L-W4C4A6-ZY2_link5" />
    <limit effort="19" lower="-3.1067" upper="3.1067" velocity="4.1887902047863905" />
    <axis xyz="0 0 1" />
    <origin rpy="0 0 0" xyz="-0.0105 0.0 0.278" />
  </joint>
  <transmission name="tran5">
    <type>transmission_interface/SimpleTransmission</type>
    <joint name="AR5-5_08L-W4C4A6-ZY2_joint_5">
      <hardwareInterface>EffortJointInterface</hardwareInterface>
    </joint>
    <actuator name="motor5">
      <hardwareInterface>EffortJointInterface</hardwareInterface>
      <mechanicalReduction>1</mechanicalReduction>
    </actuator>
  </transmission>
  <link name="AR5-5_08L-W4C4A6-ZY2_link5">
    <visual>
      <geometry>
        <mesh filename="../meshes/AR5-5_08L-W4C4A6-ZY2_link5.stl" scale="0.001 0.001 0.001" />
      </geometry>
      <origin rpy="0 0 0" xyz="0 0 0" />
      <material name="white" />
    </visual>
    <inertial>
      <mass value="1.279" />
      <inertia ixx="0.00241349" ixy="-0.00003807" ixz="-0.00004536" iyy="0.00200246" iyz="0.00006623" izz="0.00158693" />
      <origin rpy="0 0 0" xyz="-0.000756 0.000723 -0.086764" />
    </inertial>
    <collision>
      <geometry>
        <mesh filename="../meshes/AR5-5_08L-W4C4A6-ZY2_link5.stl" scale="0.001 0.001 0.001" />
      </geometry>
      <origin rpy="0 0 0" xyz="0 0 0" />
    </collision>
  </link>
  <joint name="AR5-5_08L-W4C4A6-ZY2_joint_6" type="revolute">
    <parent link="AR5-5_08L-W4C4A6-ZY2_link5" />
    <child link="AR5-5_08L-W4C4A6-ZY2_link6" />
    <limit effort="19" lower="-0.9599" upper="0.9599" velocity="4.1887902047863905" />
    <axis xyz="0 1 0" />
    <origin rpy="0.0 0.0 0" xyz="0.0 0.0 0.0" />
  </joint>
  <transmission name="tran6">
    <type>transmission_interface/SimpleTransmission</type>
    <joint name="AR5-5_08L-W4C4A6-ZY2_joint_6">
      <hardwareInterface>EffortJointInterface</hardwareInterface>
    </joint>
    <actuator name="motor6">
      <hardwareInterface>EffortJointInterface</hardwareInterface>
      <mechanicalReduction>1</mechanicalReduction>
    </actuator>
  </transmission>
  <link name="AR5-5_08L-W4C4A6-ZY2_link6">
    <visual>
      <geometry>
        <mesh filename="../meshes/AR5-5_08L-W4C4A6-ZY2_link6.stl" scale="0.001 0.001 0.001" />
      </geometry>
      <origin rpy="0 0 0" xyz="0 0 0" />
      <material name="white" />
    </visual>
    <inertial>
      <mass value="0.906" />
      <inertia ixx="0.00061429" ixy="-0.00000088" ixz="0.00000104" iyy="0.00074781" iyz="-0.00000047" izz="0.00075897" />
      <origin rpy="0 0 0" xyz="-0.005104 0.000251 5.6e-05" />
    </inertial>
    <collision>
      <geometry>
        <mesh filename="../meshes/AR5-5_08L-W4C4A6-ZY2_link6.stl" scale="0.001 0.001 0.001" />
      </geometry>
      <origin rpy="0 0 0" xyz="0 0 0" />
    </collision>
  </link>
  <joint name="AR5-5_08L-W4C4A6-ZY2_joint_7" type="revolute">
    <parent link="AR5-5_08L-W4C4A6-ZY2_link6" />
    <child link="AR5-5_08L-W4C4A6-ZY2_link7" />
    <limit effort="19" lower="-0.9599" upper="0.9599" velocity="4.1887902047863905" />
    <axis xyz="1 0 0" />
    <origin rpy="0.0 0.0 0" xyz="0.0 0.0 0.0" />
  </joint>
  <transmission name="tran7">
    <type>transmission_interface/SimpleTransmission</type>
    <joint name="AR5-5_08L-W4C4A6-ZY2_joint_7">
      <hardwareInterface>EffortJointInterface</hardwareInterface>
    </joint>
    <actuator name="motor7">
      <hardwareInterface>EffortJointInterface</hardwareInterface>
      <mechanicalReduction>1</mechanicalReduction>
    </actuator>
  </transmission>
  <link name="AR5-5_08L-W4C4A6-ZY2_link7">
    <visual>
      <geometry>
        <mesh filename="../meshes/AR5-5_08L-W4C4A6-ZY2_link7.stl" scale="0.001 0.001 0.001" />
      </geometry>
      <origin rpy="0 0 0" xyz="0.0 0.0 0.0" />
      <material name="white" />
    </visual>
    <inertial>
      <mass value="0.33" />
      <inertia ixx="0.00046062" ixy="0.00000269" ixz="0.00003859" iyy="0.00068652" iyz="-0.00000095" izz="0.00043943" />
      <origin rpy="0 0 0" xyz="-0.001562 -0.000366 0.05392" />
    </inertial>
    <collision>
      <geometry>
        <mesh filename="../meshes/AR5-5_08L-W4C4A6-ZY2_link7.stl" scale="0.001 0.001 0.001" />
      </geometry>
      <origin rpy="0 0 0" xyz="0.0 0.0 0.0" />
    </collision>
  </link>
  <link name="AR5-5_08L-W4C4A6-ZY2_flan_link">
    <inertial>
      <origin rpy="0 0 0" xyz="0 0 0" />
      <mass value="0" />
      <inertia ixx="0" ixy="0" ixz="0" iyy="0" iyz="0" izz="0" />
    </inertial>
    <visual>
      <origin xyz="0 0 0" rpy="0 0 0" />
      <geometry>
        <sphere radius="0.005" />
      </geometry>
      <material name="grey" />
    </visual>
  </link>
  <joint name="AR5-5_08L-W4C4A6-ZY2_flan_joint" type="fixed">
    <parent link="AR5-5_08L-W4C4A6-ZY2_link7" />
    <child link="AR5-5_08L-W4C4A6-ZY2_flan_link" />
    <origin rpy="0 0 0" xyz="0 0 0.09" />
  </joint>
  <link name="AR5-5_08L-W4C4A6-ZY2_link_suction_cup_base">
    <visual>
      <geometry>
        <mesh filename="../meshes/AR5-5_08L-W4C4A6-ZY2_link_suction_cup_base.stl" />
      </geometry>
      <origin rpy="0 0 0" xyz="0 0 0" />
      <material name="grey" />
    </visual>
    <inertial>
      <origin xyz="-0.01016387 0.00166764 0.04862591" rpy="0 0 0" />
      <mass value="1.00422732635" />
      <inertia ixx="0.00381085" ixy="6.744e-05" ixz="-0.00054609" iyy="0.00432244" iyz="4.154e-05" izz="0.00158135" />
    </inertial>
    <collision>
      <geometry>
        <mesh filename="../meshes/AR5-5_08L-W4C4A6-ZY2_link_suction_cup_base.stl" />
      </geometry>
      <origin rpy="0 0 0" xyz="0 0 0" />
    </collision>
  </link>
  <joint name="AR5-5_08L-W4C4A6-ZY2_joint_suction_cup_base" type="fixed">
    <origin xyz="0 0 0" rpy="0 0 0" />
    <parent link="AR5-5_08L-W4C4A6-ZY2_flan_link" />
    <child link="AR5-5_08L-W4C4A6-ZY2_link_suction_cup_base" />
  </joint>
  <link name="AR5-5_08L-W4C4A6-ZY2_link_suction_cup">
    <visual>
      <geometry>
        <mesh filename="../meshes/AR5-5_08L-W4C4A6-ZY2_link_suction_cup.stl" />
      </geometry>
      <origin rpy="0 0 0" xyz="0 0 0" />
      <material name="grey" />
    </visual>
    <inertial>
      <origin xyz="0 0 0.00318644" rpy="0 0 0" />
      <mass value="0.0423726736538" />
      <inertia ixx="2.709e-05" ixy="0" ixz="0" iyy="4.63e-06" iyz="0" izz="2.573e-05" />
    </inertial>
    <collision>
      <geometry>
        <mesh filename="../meshes/AR5-5_08L-W4C4A6-ZY2_link_suction_cup.stl" />
      </geometry>
      <origin rpy="0 0 0" xyz="0 0 0" />
    </collision>
  </link>
  <joint name="AR5-5_08L-W4C4A6-ZY2_joint_suction_cup" type="revolute">
    <origin xyz="-0.0035 0 0.2145" rpy="0 0 0" />
    <parent link="AR5-5_08L-W4C4A6-ZY2_link_suction_cup_base" />
    <child link="AR5-5_08L-W4C4A6-ZY2_link_suction_cup" />
    <axis xyz="0 1 0" />
    <limit lower="-1.5708" upper="1.5708" effort="5.0" velocity="15.708" />
  </joint>
</robot>
