<?xml version='1.0' encoding='utf-8'?>
<robot name="fr3v2_1">
  <link name="base">
      </link>
  <joint name="fr3v2_1_base_joint" type="fixed">
    <parent link="base" />
    <child link="fr3v2_1_link0" />
    <origin rpy="0 0 0" xyz="0 0 0" />
  </joint>
  <link name="fr3v2_1_link0">
    <visual name="fr3v2_1_link0_visual">
      <geometry>
        <mesh filename="package://human_data/urdf/fr3v2_1_link0.stl" />
      </geometry>
    </visual>
    <collision name="fr3v2_1_link0_collision">
      <geometry>
        <mesh filename="package://human_data/urdf/fr3v2_1_link0.stl" />
      </geometry>
    </collision>
    <inertial>
      <origin rpy="0 0 0" xyz="-0.017200 0.000400 0.074500" />
      <mass value="2.3966" />
      <inertia ixx="0.009" ixy="0.0" ixz="0.002" iyy="0.0115" iyz="0.0" izz="0.0085" />
    </inertial>
  </link>
  <link name="fr3v2_1_link1">
    <visual name="fr3v2_1_link1_visual">
      <geometry>
        <mesh filename="package://human_data/urdf/fr3v2_1_link0.stl" />
      </geometry>
    </visual>
    <collision name="fr3v2_1_link1_collision">
      <geometry>
        <mesh filename="package://human_data/urdf/fr3v2_1_link0.stl" />
      </geometry>
    </collision>
    <inertial>
      <origin rpy="0 0 0" xyz="-0.004580 0.027016 -0.061800" />
      <mass value="2.4377" />
      <inertia ixx="0.02324" ixy="0.000333" ixz="-0.000676" iyy="0.02146" iyz="0.003739" izz="0.0055" />
    </inertial>
  </link>
  <joint name="fr3v2_1_joint1" type="revolute">
    <origin rpy="0 0 0" xyz="0 0 0.333" />
    <parent link="fr3v2_1_link0" />
    <child link="fr3v2_1_link1" />
    <axis xyz="0 0 1" />
    <limit effort="87.0" lower="-2.9007400166666666" upper="2.9007400166666666" velocity="2.62" />
    <safety_controller k_position="100.0" k_velocity="40.0" soft_lower_limit="-2.9007400166666666" soft_upper_limit="2.9007400166666666" />
    <position_based_velocity_limits deceleration_limit="6.0" velocity_offset="0.6520000381679385" />
    <dynamics D="1" K="7000" damping="0.003" friction="0.2" gear_ratio="120.0" motor_inertia="4.206399e-05" mu_coulomb="0" mu_viscous="16" />
  </joint>
  <link name="fr3v2_1_link2">
    <visual name="fr3v2_1_link2_visual">
      <geometry>
        <mesh filename="package://human_data/urdf/fr3v2_1_link0.stl" />
      </geometry>
    </visual>
    <collision name="fr3v2_1_link2_collision">
      <geometry>
        <mesh filename="package://human_data/urdf/fr3v2_1_link0.stl" />
      </geometry>
    </collision>
    <inertial>
      <origin rpy="0 0 0" xyz="-0.010630 -0.184739 -0.010479" />
      <mass value="2.2375" />
      <inertia ixx="0.019026" ixy="0.001241" ixz="0.000499" iyy="0.00566" iyz="-0.001804" izz="0.017114" />
    </inertial>
  </link>
  <joint name="fr3v2_1_joint2" type="revolute">
    <origin rpy="-1.570796326794897 0 0" xyz="0 0 0" />
    <parent link="fr3v2_1_link1" />
    <child link="fr3v2_1_link2" />
    <axis xyz="0 0 1" />
    <limit effort="87.0" lower="-1.8360900166666667" upper="1.8360900166666667" velocity="2.62" />
    <safety_controller k_position="100.0" k_velocity="40.0" soft_lower_limit="-1.8360900166666667" soft_upper_limit="1.8360900166666667" />
    <position_based_velocity_limits deceleration_limit="2.585" velocity_offset="0.2499685851463105" />
    <dynamics D="1" K="7000" damping="0.003" friction="0.2" gear_ratio="120.0" motor_inertia="4.206399e-05" mu_coulomb="0" mu_viscous="16" />
  </joint>
  <link name="fr3v2_1_link3">
    <visual name="fr3v2_1_link3_visual">
      <geometry>
        <mesh filename="package://human_data/urdf/fr3v2_1_link0.stl" />
      </geometry>
    </visual>
    <collision name="fr3v2_1_link3_collision">
      <geometry>
        <mesh filename="package://human_data/urdf/fr3v2_1_link0.stl" />
      </geometry>
    </collision>
    <inertial>
      <origin rpy="0 0 0" xyz="0.091995 0.023003 0.047348" />
      <mass value="2.196382" />
      <inertia ixx="0.010225" ixy="0.001144" ixz="0.003497" iyy="0.012398" iyz="0.002156" izz="0.006877" />
    </inertial>
  </link>
  <joint name="fr3v2_1_joint3" type="revolute">
    <origin rpy="1.570796326794897 0 0" xyz="0 -0.316 0" />
    <parent link="fr3v2_1_link2" />
    <child link="fr3v2_1_link3" />
    <axis xyz="0 0 1" />
    <limit effort="87.0" lower="-2.9007400166666666" upper="2.9007400166666666" velocity="2.62" />
    <safety_controller k_position="100.0" k_velocity="40.0" soft_lower_limit="-2.9007400166666666" soft_upper_limit="2.9007400166666666" />
    <position_based_velocity_limits deceleration_limit="3.5" velocity_offset="0.20053055661577582" />
    <dynamics D="1" K="7000" damping="0.003" friction="0.2" gear_ratio="120.0" motor_inertia="3.211626e-05" mu_coulomb="0" mu_viscous="16" />
  </joint>
  <link name="fr3v2_1_link4">
    <visual name="fr3v2_1_link4_visual">
      <geometry>
        <mesh filename="package://human_data/urdf/fr3v2_1_link0.stl" />
      </geometry>
    </visual>
    <collision name="fr3v2_1_link4_collision">
      <geometry>
        <mesh filename="package://human_data/urdf/fr3v2_1_link0.stl" />
      </geometry>
    </collision>
    <inertial>
      <origin rpy="0 0 0" xyz="-0.084334 0.096836 0.006248" />
      <mass value="2.186422" />
      <inertia ixx="0.008878" ixy="-0.003749" ixz="0.001139" iyy="0.007628" iyz="-0.00046" izz="0.010295" />
    </inertial>
  </link>
  <joint name="fr3v2_1_joint4" type="revolute">
    <origin rpy="1.570796326794897 0 0" xyz="0.0825 0 0" />
    <parent link="fr3v2_1_link3" />
    <child link="fr3v2_1_link4" />
    <axis xyz="0 0 1" />
    <limit effort="87.0" lower="-3.077020016666667" upper="-0.11693708333333333" velocity="2.62" />
    <safety_controller k_position="100.0" k_velocity="40.0" soft_lower_limit="-3.077020016666667" soft_upper_limit="-0.11693708333333333" />
    <position_based_velocity_limits deceleration_limit="4.0" velocity_offset="0.3542181933842238" />
    <dynamics D="1" K="7000" damping="0.003" friction="0.2" gear_ratio="120.0" motor_inertia="3.211626e-05" mu_coulomb="0" mu_viscous="16" />
  </joint>
  <link name="fr3v2_1_link5">
    <visual name="fr3v2_1_link5_visual">
      <geometry>
        <mesh filename="package://human_data/urdf/fr3v2_1_link0.stl" />
      </geometry>
    </visual>
    <collision name="fr3v2_1_link5_collision">
      <geometry>
        <mesh filename="package://human_data/urdf/fr3v2_1_link0.stl" />
      </geometry>
    </collision>
    <inertial>
      <origin rpy="0 0 0" xyz="0.000039 0.011821 -0.054936" />
      <mass value="2.190783" />
      <inertia ixx="0.031874" ixy="0.000134" ixz="-0.000265" iyy="0.029674" iyz="-0.004734" izz="0.004751" />
    </inertial>
  </link>
  <joint name="fr3v2_1_joint5" type="revolute">
    <origin rpy="-1.570796326794897 0 0" xyz="-0.0825 0.384 0" />
    <parent link="fr3v2_1_link4" />
    <child link="fr3v2_1_link5" />
    <axis xyz="0 0 1" />
    <limit effort="12.0" lower="-2.87630335" upper="2.87630335" velocity="5.26" />
    <safety_controller k_position="100.0" k_velocity="40.0" soft_lower_limit="-2.87630335" soft_upper_limit="2.87630335" />
    <position_based_velocity_limits deceleration_limit="17.0" velocity_offset="0.5738321197718637" />
    <dynamics D="1" K="7000" damping="0.003" friction="0.2" gear_ratio="80.0" motor_inertia="3.211626e-05" mu_coulomb="0" mu_viscous="16" />
  </joint>
  <link name="fr3v2_1_link6">
    <visual name="fr3v2_1_link6_visual">
      <geometry>
        <mesh filename="package://human_data/urdf/fr3v2_1_link0.stl" />
      </geometry>
    </visual>
    <collision name="fr3v2_1_link6_collision">
      <geometry>
        <mesh filename="package://human_data/urdf/fr3v2_1_link0.stl" />
      </geometry>
    </collision>
    <inertial>
      <origin rpy="0 0 0" xyz="0.069627 -0.016716 -0.037235" />
      <mass value="1.583583" />
      <inertia ixx="0.00286" ixy="-0.000553" ixz="-0.000638" iyy="0.00391" iyz="-0.00024" izz="0.00453" />
    </inertial>
  </link>
  <joint name="fr3v2_1_joint6" type="revolute">
    <origin rpy="1.570796326794897 0 0" xyz="0 0 0" />
    <parent link="fr3v2_1_link5" />
    <child link="fr3v2_1_link6" />
    <axis xyz="0 0 1" />
    <limit effort="12.0" lower="0.43982265" upper="4.62163335" velocity="4.18" />
    <safety_controller k_position="100.0" k_velocity="40.0" soft_lower_limit="0.43982265" soft_upper_limit="4.62163335" />
    <position_based_velocity_limits deceleration_limit="5.5" velocity_offset="0.4884649342105264" />
    <dynamics D="1" K="7000" damping="0.003" friction="0.2" gear_ratio="80.0" motor_inertia="3.211626e-05" mu_coulomb="0" mu_viscous="16" />
  </joint>
  <link name="fr3v2_1_link7">
    <visual name="fr3v2_1_link7_visual">
      <geometry>
        <mesh filename="package://human_data/urdf/fr3v2_1_link0.stl" />
      </geometry>
    </visual>
    <collision name="fr3v2_1_link7_collision">
      <geometry>
        <mesh filename="package://human_data/urdf/fr3v2_1_link0.stl" />
      </geometry>
    </collision>
    <inertial>
      <origin rpy="0 0 0" xyz="-0.014555 0.009230 0.065858" />
      <mass value="0.698686" />
      <inertia ixx="0.000899" ixy="0.0" ixz="-1.3e-05" iyy="0.001099" iyz="-2.2e-05" izz="0.000702" />
    </inertial>
  </link>
  <joint name="fr3v2_1_joint7" type="revolute">
    <origin rpy="1.570796326794897 0 0" xyz="0.088 0 0" />
    <parent link="fr3v2_1_link6" />
    <child link="fr3v2_1_link7" />
    <axis xyz="0 0 1" />
    <limit effort="12.0" lower="-3.05083335" upper="3.05083335" velocity="5.26" />
    <safety_controller k_position="100.0" k_velocity="40.0" soft_lower_limit="-3.05083335" soft_upper_limit="3.05083335" />
    <position_based_velocity_limits deceleration_limit="17.0" velocity_offset="0.4591952376425851" />
    <dynamics D="1" K="7000" damping="0.003" friction="0.2" gear_ratio="80.0" motor_inertia="3.211626e-05" mu_coulomb="0" mu_viscous="16" />
  </joint>
  <link name="fr3v2_1_link8" />
  <joint name="fr3v2_1_joint8" type="fixed">
    <origin rpy="0 0 0" xyz="0 0 0.107" />
    <parent link="fr3v2_1_link7" />
    <child link="fr3v2_1_link8" />
  </joint>
  <joint name="fr3v2_1_hand_joint" type="fixed">
    <parent link="fr3v2_1_link8" />
    <child link="fr3v2_1_hand" />
    <origin rpy="0 0 -0.7853981633974483" xyz="0 0 0" />
  </joint>
  <link name="fr3v2_1_hand">
    <visual name="fr3v2_1_hand_visual">
      <geometry>
        <mesh filename="package://human_data/urdf/fr3v2_1_link0.stl" />
      </geometry>
    </visual>
    <collision name="fr3v2_1_hand_collision">
      <geometry>
        <mesh filename="package://human_data/urdf/fr3v2_1_link0.stl" />
      </geometry>
    </collision>
    <inertial>
      <origin rpy="0 0 0" xyz="-0.0000376 0.0119128 0.0207260" />
      <mass value="0.6544" />
      <inertia ixx="0.00186" ixy="0.0" ixz="0.0" iyy="0.0003" iyz="-2e-05" izz="0.00174" />
    </inertial>
  </link>
  <link name="fr3v2_1_hand_tcp" />
  <joint name="fr3v2_1_hand_tcp_joint" type="fixed">
    <origin rpy="0 0 0" xyz="0 0 0.1034" />
    <parent link="fr3v2_1_hand" />
    <child link="fr3v2_1_hand_tcp" />
  </joint>
  <link name="fr3v2_1_leftfinger">
    <visual name="fr3v2_1_leftfinger_visual">
      <geometry>
        <mesh filename="package://human_data/urdf/fr3v2_1_link0.stl" />
      </geometry>
    </visual>
    <collision>
      <origin rpy="0 0 0" xyz="0 18.5e-3 11e-3" />
      <geometry>
        <box size="22e-3 15e-3 20e-3" />
      </geometry>
    </collision>
    <collision>
      <origin rpy="0 0 0" xyz="0 6.8e-3 2.2e-3" />
      <geometry>
        <box size="22e-3 8.8e-3 3.8e-3" />
      </geometry>
    </collision>
    <collision>
      <origin rpy="0.5235987755982988 0 0" xyz="0 15.9e-3 28.35e-3" />
      <geometry>
        <box size="17.5e-3 7e-3 23.5e-3" />
      </geometry>
    </collision>
    <collision>
      <origin rpy="0 0 0" xyz="0 7.58e-3 45.25e-3" />
      <geometry>
        <box size="17.5e-3 15.2e-3 18.5e-3" />
      </geometry>
    </collision>
    <inertial>
      <origin rpy="0 0 0" xyz="0 0.0152850 0.0219675" />
      <mass value="0.0291" />
      <inertia ixx="8.49e-06" ixy="0.0" ixz="0.0" iyy="8.53e-06" iyz="-1.06e-06" izz="1.77e-06" />
    </inertial>
  </link>
  <link name="fr3v2_1_rightfinger">
    <visual name="fr3v2_1_rightfinger_visual">
      <origin rpy="0 0 0" xyz="0 0 0" />
      <geometry>
        <mesh filename="package://human_data/urdf/fr3v2_1_link0.stl" />
      </geometry>
    </visual>
    <collision>
      <origin rpy="0 0 0" xyz="0 18.5e-3 11e-3" />
      <geometry>
        <box size="22e-3 15e-3 20e-3" />
      </geometry>
    </collision>
    <collision>
      <origin rpy="0 0 0" xyz="0 6.8e-3 2.2e-3" />
      <geometry>
        <box size="22e-3 8.8e-3 3.8e-3" />
      </geometry>
    </collision>
    <collision>
      <origin rpy="-0.5235987755982988 0 3.141592653589793" xyz="0 15.9e-3 28.35e-3" />
      <geometry>
        <box size="17.5e-3 7e-3 23.5e-3" />
      </geometry>
    </collision>
    <collision>
      <origin rpy="0 0 0" xyz="0 7.58e-3 45.25e-3" />
      <geometry>
        <box size="17.5e-3 15.2e-3 18.5e-3" />
      </geometry>
    </collision>
    <inertial>
      <origin rpy="0 0 0" xyz="0 0.0152850 0.0219675" />
      <mass value="0.0291" />
      <inertia ixx="8.49e-06" ixy="0.0" ixz="0.0" iyy="8.53e-06" iyz="-1.06e-06" izz="1.77e-06" />
    </inertial>
  </link>
  <joint name="fr3v2_1_finger_joint1" type="prismatic">
    <parent link="fr3v2_1_hand" />
    <child link="fr3v2_1_leftfinger" />
    <origin rpy="0 0 0" xyz="0 0 0.0584" />
    <axis xyz="0 1 0" />
    <limit effort="100" lower="0.0" upper="0.04" velocity="0.2" />
    <dynamics damping="0.3" />
  </joint>
  <joint name="fr3v2_1_finger_joint2_fixed" type="fixed">
    <parent link="fr3v2_1_hand" />
    <child link="fr3v2_1_rightfinger" />
    <origin rpy="0 0 3.141592653589793" xyz="0 0 0.0584" />
    <axis xyz="0 1 0" />
    <limit effort="100" lower="0.0" upper="0.04" velocity="0.2" />
    <mimic joint="fr3v2_1_finger_joint1" />
    <dynamics damping="0.3" />
  </joint>
</robot>
