<?xml version='1.0' encoding='utf-8'?>
<mujoco model="piper">
  <compiler angle="radian" meshdir="../meshes" />
  <asset>
    <mesh name="base_link" content_type="model/stl" file="base_link.STL" />
    <mesh name="link1" content_type="model/stl" file="link1.STL" />
    <mesh name="link2" content_type="model/stl" file="link2.STL" />
    <mesh name="link3" content_type="model/stl" file="link3.STL" />
    <mesh name="link4" content_type="model/stl" file="link4.STL" />
    <mesh name="link5" content_type="model/stl" file="link5.STL" />
    <mesh name="link6" content_type="model/stl" file="link6.STL" />
    <mesh name="gripper_base" content_type="model/stl" file="gripper_base.STL" />
    <mesh name="link7" content_type="model/stl" file="link7.STL" />
    <mesh name="link8" content_type="model/stl" file="link8.STL" />
  </asset>
  <worldbody>
    <geom type="mesh" rgba="0.792157 0.819608 0.933333 1" mesh="base_link" contype="0" conaffinity="0" density="0" group="1" />
    <body name="link1" pos="0 0 0.123">
      <inertial pos="0.00032 -0.00041 -0.00348" quat="0.737007 0.671914 -0.0484837 0.0547877" mass="0.71" diaginertia="0.0005012 0.00045752 0.00040836" />
      <joint name="joint1" pos="0 0 0" axis="0 0 1" range="-2.618 2.618" actuatorfrcrange="-100 100" />
      <geom type="mesh" rgba="0.792157 0.819608 0.933333 1" mesh="link1" contype="1" conaffinity="15" density="0" group="0" />
      <body name="link2" quat="0.0480084 -0.0480134 -0.705476 -0.705474">
        <inertial pos="0.21852 -0.00861 0.00126" quat="0.479919 0.532436 0.466857 0.517913" mass="1.16" diaginertia="0.0676841 0.0675582 0.00106833" />
        <joint name="joint2" pos="0 0 0" axis="0 0 1" range="0 3.14" actuatorfrcrange="-100 100" />
        <geom type="mesh" rgba="0.792157 0.819608 0.933333 1" mesh="link2" contype="1" conaffinity="15" density="0" group="0" />
        <body name="link3" pos="0.28503 0 0" quat="0.623996 0 0 -0.781427">
          <inertial pos="-0.01999 -0.14808 -0.00053" quat="0.70534 0.70619 0.0352022 0.0505251" mass="0.5" diaginertia="0.0136724 0.0136332 0.000267444" />
          <joint name="joint3" pos="0 0 0" axis="0 0 1" range="-2.967 0" actuatorfrcrange="-100 100" />
          <geom type="mesh" rgba="0.792157 0.819608 0.933333 1" mesh="link3" contype="1" conaffinity="15" density="0" group="0" />
          <body name="link4" pos="-0.021984 -0.25075 0" quat="0.707105 0.707108 0 0">
            <inertial pos="0.00013 -0.00076 -0.00394" quat="0.727848 0.0276487 -0.0387803 0.684082" mass="0.38" diaginertia="0.000189565 0.00017841 0.000145735" />
            <joint name="joint4" pos="0 0 0" axis="0 0 1" range="-1.745 1.745" actuatorfrcrange="-100 100" />
            <geom type="mesh" rgba="0.792157 0.819608 0.933333 1" mesh="link4" contype="1" conaffinity="15" density="0" group="0" />
            <body name="link5" quat="0.707105 -0.707108 0 0">
              <inertial pos="0.00018 -0.06104 -0.00227" quat="0.709375 0.704813 -0.00301298 0.00422225" mass="0.383" diaginertia="0.00172319 0.00171178 0.000179292" />
              <joint name="joint5" pos="0 0 0" axis="0 0 1" range="-1.22 1.22" actuatorfrcrange="-100 100" />
              <geom type="mesh" rgba="0.792157 0.819608 0.933333 1" mesh="link5" contype="1" conaffinity="15" density="0" group="0" />
              <body name="link6" pos="8.8259e-05 -0.091 0" quat="0.707105 0.707108 0 0">
                <inertial pos="-0.000181451 8.01893e-05 0.0323587" quat="0.999993 3.27167e-05 0.0013705 0.00337339" mass="0.457" diaginertia="0.00245185 0.00210207 0.000705927" />
                <joint name="joint6" pos="0 0 0" axis="0 0 1" range="-2.0944 2.0944" actuatorfrcrange="-100 100" />
                <geom type="mesh" rgba="0.898039 0.917647 0.929412 1" mesh="link6" contype="1" conaffinity="15" density="0" group="0" />
                <geom type="mesh" rgba="0.792157 0.819608 0.933333 1" mesh="gripper_base" contype="1" conaffinity="15" density="0" group="0" />
                <body name="link7" pos="0 0 0.1358" quat="0.707105 0.707108 0 0">
                  <inertial pos="0.000651232 -0.049193 0.00972259" quat="0.301719 0.664591 -0.635911 0.250804" mass="0.025" diaginertia="8.79953e-05 7.36823e-05 6.04424e-05" />
                  <joint name="joint7" pos="0 0 0" axis="0 0 1" type="slide" range="0 0.035" actuatorfrcrange="-10 10" />
                  <geom type="mesh" rgba="0.792157 0.819608 0.933333 1" mesh="link7" contype="1" conaffinity="15" density="0" group="0" />
                </body>
                <body name="link8" pos="0 0 0.1358" quat="-2.59734e-06 -2.59735e-06 -0.707108 -0.707105">
                  <inertial pos="0.000651232 -0.049193 0.00972259" quat="0.301719 0.664591 -0.635911 0.250804" mass="0.025" diaginertia="8.79953e-05 7.36823e-05 6.04424e-05" />
                  <joint name="joint8" pos="0 0 0" axis="0 0 -1" type="slide" range="-0.035 0" actuatorfrcrange="-10 10" />
                  <geom type="mesh" rgba="0.792157 0.819608 0.933333 1" mesh="link8" contype="1" conaffinity="15" density="0" group="0" />
                </body>
              </body>
            </body>
          </body>
        </body>
      </body>
    </body>
  </worldbody>
</mujoco>
