<?xml version="1.0" encoding="utf-8"?>
<!-- This URDF was automatically created by SolidWorks to URDF Exporter! Originally created by Stephen Brawner (brawner@gmail.com) 
     Commit Version: 1.6.0-1-g15f4949  Build Version: 1.6.7594.29634
     For more information, please see http://wiki.ros.org/sw_urdf_exporter -->
<robot
  name="nexus-arm">
  <link
    name="base_link">
    <inertial>
      <origin
        xyz="0.00155409 -0.00036544 0.0688395"
        rpy="0 0 0" />
      <mass
        value="0.95628283" />
      <inertia
        ixx="0.00207332"
        ixy="-1.672e-05"
        ixz="1.199e-05"
        iyy="0.00216568"
        iyz="-1.92e-06"
        izz="0.00088767" />
    </inertial>
    <visual>
      <origin
        xyz="0 0 0"
        rpy="0 0 0" />
      <geometry>
        <mesh
          filename="package://Tele-arm-right.SLDASM/meshes/base_link.STL" />
      </geometry>
      <material
        name="">
        <color
          rgba="0.752941176470588 0.752941176470588 0.752941176470588 1" />
      </material>
    </visual>
    <collision>
      <origin
        xyz="0 0 0"
        rpy="0 0 0" />
      <geometry>
        <mesh
          filename="package://Tele-arm-right.SLDASM/meshes/base_link.STL" />
      </geometry>
    </collision>
  </link>
  <link
    name="link1_Link">
    <inertial>
      <origin
        xyz="-0.00016706 -0.01517284 0.03109056"
        rpy="0 0 0" />
      <mass
        value="0.08712006" />
      <inertia
        ixx="8.047e-05"
        ixy="-1.1e-07"
        ixz="-1.8e-07"
        iyy="7.463e-05"
        iyz="-2.499e-05"
        izz="5.083e-05" />
    </inertial>
    <visual>
      <origin
        xyz="0 0 0"
        rpy="0 0 0" />
      <geometry>
        <mesh
          filename="package://Tele-arm-right.SLDASM/meshes/link1_Link.STL" />
      </geometry>
      <material
        name="">
        <color
          rgba="0.75294 0.75294 0.75294 1" />
      </material>
    </visual>
    <collision>
      <origin
        xyz="0 0 0"
        rpy="0 0 0" />
      <geometry>
        <mesh
          filename="package://Tele-arm-right.SLDASM/meshes/link1_Link.STL" />
      </geometry>
    </collision>
  </link>
  <joint
    name="link1_Joint"
    type="revolute">
    <origin
      xyz="0 0 0.13305"
      rpy="0 0 0" />
    <parent
      link="base_link" />
    <child
      link="link1_Link" />
    <axis
      xyz="0 0 1" />
    <limit
      lower="-1.5708"
      upper="1.5708"
      effort="9"
      velocity="3.77" />
  </joint>
  <link
    name="link2_Link">
    <inertial>
      <origin
        xyz="0.00106133 0.02987296 0.0650682"
        rpy="0 0 0" />
      <mass
        value="0.85624673" />
      <inertia
        ixx="0.00390267"
        ixy="2.025e-05"
        ixz="-1.5e-06"
        iyy="0.00383255"
        iyz="-1.83e-06"
        izz="0.00044701" />
    </inertial>
    <visual>
      <origin
        xyz="0 0 0"
        rpy="0 0 0" />
      <geometry>
        <mesh
          filename="package://Tele-arm-right.SLDASM/meshes/link2_Link.STL" />
      </geometry>
      <material
        name="">
        <color
          rgba="0.752941176470588 0.752941176470588 0.752941176470588 1" />
      </material>
    </visual>
    <collision>
      <origin
        xyz="0 0 0"
        rpy="0 0 0" />
      <geometry>
        <mesh
          filename="package://Tele-arm-right.SLDASM/meshes/link2_Link.STL" />
      </geometry>
    </collision>
  </link>
  <joint
    name="link2_Joint"
    type="revolute">
    <origin
      xyz="0 -0.026125 0.0605"
      rpy="0 0 0" />
    <parent
      link="link1_Link" />
    <child
      link="link2_Link" />
    <axis
      xyz="0 1 0" />
    <limit
      lower="-1.2217"
      upper="0.6981"
      effort="9"
      velocity="3.77" />
  </joint>
  <link
    name="link3_Link">
    <inertial>
      <origin
        xyz="-0.06853245 0.02112503 9.764e-05"
        rpy="0 0 0" />
      <mass
        value="0.25653271" />
      <inertia
        ixx="0.00011274"
        ixy="-7.512e-05"
        ixz="-1.25e-06"
        iyy="0.00032987"
        iyz="4.8e-07"
        izz="0.00034799" />
    </inertial>
    <visual>
      <origin
        xyz="0 0 0"
        rpy="0 0 0" />
      <geometry>
        <mesh
          filename="package://Tele-arm-right.SLDASM/meshes/link3_Link.STL" />
      </geometry>
      <material
        name="">
        <color
          rgba="0.752941176470588 0.752941176470588 0.752941176470588 1" />
      </material>
    </visual>
    <collision>
      <origin
        xyz="0 0 0"
        rpy="0 0 0" />
      <geometry>
        <mesh
          filename="package://Tele-arm-right.SLDASM/meshes/link3_Link.STL" />
      </geometry>
    </collision>
  </link>
  <joint
    name="link3_Joint"
    type="revolute">
    <origin
      xyz="0 0 0.13"
      rpy="0 0 0" />
    <parent
      link="link2_Link" />
    <child
      link="link3_Link" />
    <axis
      xyz="0 1 0" />
    <limit
      lower="-0.7854"
      upper="1.3963"
      effort="9"
      velocity="3.77" />
  </joint>
  <link
    name="link4_Link">
    <inertial>
      <origin
        xyz="-0.11149055 3.179e-05 -0.06914762"
        rpy="0 0 0" />
      <mass
        value="0.3023272" />
      <inertia
        ixx="0.00035205"
        ixy="-3.67e-06"
        ixz="0.00038261"
        iyy="0.00127653"
        iyz="-1.36e-06"
        izz="0.00101995" />
    </inertial>
    <visual>
      <origin
        xyz="0 0 0"
        rpy="0 0 0" />
      <geometry>
        <mesh
          filename="package://Tele-arm-right.SLDASM/meshes/link4_Link.STL" />
      </geometry>
      <material
        name="">
        <color
          rgba="0.75294 0.75294 0.75294 1" />
      </material>
    </visual>
    <collision>
      <origin
        xyz="0 0 0"
        rpy="0 0 0" />
      <geometry>
        <mesh
          filename="package://Tele-arm-right.SLDASM/meshes/link4_Link.STL" />
      </geometry>
    </collision>
  </link>
  <joint
    name="link4_Joint"
    type="revolute">
    <origin
      xyz="-0.09 0.026125 0"
      rpy="0 0 0" />
    <parent
      link="link3_Link" />
    <child
      link="link4_Link" />
    <axis
      xyz="1 0 0" />
    <limit
      lower="-0.6981"
      upper="2.0944"
      effort="0.8"
      velocity="15.708" />
  </joint>
  <link
    name="link5_Link">
    <inertial>
      <origin
        xyz="-0.02493969 -0.07750726 0.059897"
        rpy="0 0 0" />
      <mass
        value="0.26897353" />
      <inertia
        ixx="0.00052718"
        ixy="7.073e-05"
        ixz="-7.742e-05"
        iyy="0.00029891"
        iyz="-0.00000095"
        izz="0.00037371" />
    </inertial>
    <visual>
      <origin
        xyz="0 0 0"
        rpy="0 0 0" />
      <geometry>
        <mesh
          filename="package://Tele-arm-right.SLDASM/meshes/link5_Link.STL" />
      </geometry>
      <material
        name="">
        <color
          rgba="0.752941176470588 0.752941176470588 0.752941176470588 1" />
      </material>
    </visual>
    <collision>
      <origin
        xyz="0 0 0"
        rpy="0 0 0" />
      <geometry>
        <mesh
          filename="package://Tele-arm-right.SLDASM/meshes/link5_Link.STL" />
      </geometry>
    </collision>
  </link>
  <joint
    name="link5_Joint"
    type="revolute">
    <origin
      xyz="-0.149385325410789 0 -0.0739103626009013"
      rpy="0 0 0" />
    <parent
      link="link4_Link" />
    <child
      link="link5_Link" />
    <axis
      xyz="-0.38268343236509 0 0.923879532511287" />
    <limit
      lower="-0.8727"
      upper="0.8727"
      effort="0.8"
      velocity="15.708" />
  </joint>
  <link
    name="link6_Link">
    <inertial>
      <origin
        xyz="0.01809394 0.15001056 -1.522e-05"
        rpy="0 0 0" />
      <mass
        value="0.37570857" />
      <inertia
        ixx="0.00116548"
        ixy="0.0001969"
        ixz="7.1e-07"
        iyy="0.00028641"
        iyz="-2.18e-06"
        izz="0.00130007" />
    </inertial>
    <visual>
      <origin
        xyz="0 0 0"
        rpy="0 0 0" />
      <geometry>
        <mesh
          filename="package://Tele-arm-right.SLDASM/meshes/link6_Link.STL" />
      </geometry>
      <material
        name="">
        <color
          rgba="0.75294 0.75294 0.75294 1" />
      </material>
    </visual>
    <collision>
      <origin
        xyz="0 0 0"
        rpy="0 0 0" />
      <geometry>
        <mesh
          filename="package://Tele-arm-right.SLDASM/meshes/link6_Link.STL" />
      </geometry>
    </collision>
  </link>
  <joint
    name="link6_Joint"
    type="revolute">
    <origin
      xyz="-0.030615 -0.08 0.07391"
      rpy="0 0 0" />
    <parent
      link="link5_Link" />
    <child
      link="link6_Link" />
    <axis
      xyz="0 1 0" />
    <limit
      lower="-0.7854"
      upper="3.1416"
      effort="0.8"
      velocity="15.708" />
  </joint>
  <link
    name="gripper_Link">
    <inertial>
      <origin
        xyz="-0.00285473 0.01042859 0"
        rpy="0 0 0" />
      <mass
        value="0.00447781" />
      <inertia
        ixx="6.7e-07"
        ixy="-1.2e-07"
        ixz="0"
        iyy="2.7e-07"
        iyz="0"
        izz="7.9e-07" />
    </inertial>
    <visual>
      <origin
        xyz="0 0 0"
        rpy="0 0 0" />
      <geometry>
        <mesh
          filename="package://Tele-arm-right.SLDASM/meshes/gripper_Link.STL" />
      </geometry>
      <material
        name="">
        <color
          rgba="1 1 1 1" />
      </material>
    </visual>
    <collision>
      <origin
        xyz="0 0 0"
        rpy="0 0 0" />
      <geometry>
        <mesh
          filename="package://Tele-arm-right.SLDASM/meshes/gripper_Link.STL" />
      </geometry>
    </collision>
  </link>
  <joint
    name="gripper_Joint"
    type="prismatic">
    <origin
      xyz="0.029809 0.1198 0"
      rpy="0 0 0" />
    <parent
      link="link6_Link" />
    <child
      link="gripper_Link" />
    <axis
      xyz="0.97815 0.20791 0" />
    <limit
      lower="0"
      upper="0.03"
      effort="0.8"
      velocity="15.708" />
  </joint>
  <link
    name="force_Link">
    <inertial>
      <origin
        xyz="3.99680288865056E-15 -5.18629974520184E-15 1.72084568816899E-15"
        rpy="0 0 0" />
      <mass
        value="0.00271300000000001" />
      <inertia
        ixx="4.5216666666667E-08"
        ixy="-1.83704223536859E-24"
        ixz="3.7256247101131E-23"
        iyy="4.5216666666667E-08"
        iyz="7.38046511500888E-25"
        izz="4.52166666666669E-08" />
    </inertial>
    <visual>
      <origin
        xyz="0 0 0"
        rpy="0 0 0" />
      <geometry>
        <mesh
          filename="package://Tele-arm-right.SLDASM/meshes/force_Link.STL" />
      </geometry>
      <material
        name="">
        <color
          rgba="0.792156862745098 0.819607843137255 0.933333333333333 1" />
      </material>
    </visual>
    <collision>
      <origin
        xyz="0 0 0"
        rpy="0 0 0" />
      <geometry>
        <mesh
          filename="package://Tele-arm-right.SLDASM/meshes/force_Link.STL" />
      </geometry>
    </collision>
  </link>
  <joint
    name="force_Joint"
    type="fixed">
    <origin
      xyz="0 0.0799999999999974 0"
      rpy="0 0 0" />
    <parent
      link="link6_Link" />
    <child
      link="force_Link" />
    <axis
      xyz="0 0 0" />
  </joint>
</robot>