<?xml version="1.0" encoding="UTF-8"?>
<!-- AR5-5_07L-W4C4A2：CBF 球化碰撞模型（与 cbf_y1_spherized.urdf 同目录 src/oscbf）
     - 关节树、轴向、原点、limit 与 AR5-5_07L-W4C4A2.urdf 一致
     - 连杆名保持 AR5-5_07L-W4C4A2_*，与 arm_control_ar5.yaml 中 collision_pairs 一致
     - 碰撞为球体包络，便于 hpp-fcl / 整臂避障；控制与正解仍用完整网格 URDF -->
<robot name="AR5-5_07L-W4C4A2">
  <link name="world"/>

  <link name="AR5-5_07L-W4C4A2_base">
    <inertial>
      <origin xyz="0 0 0.04" rpy="0 0 0"/>
      <mass value="5.0"/>
      <inertia ixx="0.02" ixy="0" ixz="0" iyy="0.02" iyz="0" izz="0.02"/>
    </inertial>
    <collision>
      <origin xyz="0 0 0.04" rpy="0 0 0"/>
      <geometry>
        <sphere radius="0.09"/>
      </geometry>
    </collision>
  </link>

  <link name="AR5-5_07L-W4C4A2_link1">
    <inertial>
      <mass value="2.683"/>
      <inertia ixx="0.00493673" ixy="0.00000160" ixz="0.00000198" iyy="0.00452344" iyz="-0.00000020" izz="0.00432910"/>
      <origin xyz="0 0 0.167909" rpy="0 0 0"/>
    </inertial>
    <collision>
      <origin xyz="0 0 0.09" rpy="0 0 0"/>
      <geometry>
        <sphere radius="0.075"/>
      </geometry>
    </collision>
    <collision>
      <origin xyz="0 0 0.22" rpy="0 0 0"/>
      <geometry>
        <sphere radius="0.055"/>
      </geometry>
    </collision>
  </link>

  <link name="AR5-5_07L-W4C4A2_link2">
    <inertial>
      <mass value="2.3"/>
      <inertia ixx="0.01151906" ixy="0.00000246" ixz="-0.00000055" iyy="0.00993335" iyz="0.00082477" izz="0.00435237"/>
      <origin xyz="0 -0.003081 0.102986" rpy="0 0 0"/>
    </inertial>
    <collision>
      <origin xyz="0 0 0.08" rpy="0 0 0"/>
      <geometry>
        <sphere radius="0.07"/>
      </geometry>
    </collision>
    <collision>
      <origin xyz="0 0 0.22" rpy="0 0 0"/>
      <geometry>
        <sphere radius="0.065"/>
      </geometry>
    </collision>
  </link>

  <link name="AR5-5_07L-W4C4A2_link3">
    <inertial>
      <mass value="1.862"/>
      <inertia ixx="0.00519681" ixy="0.00001208" ixz="0.00035761" iyy="0.00470446" iyz="0.00003430" izz="0.00266752"/>
      <origin xyz="0.007097 -0.000659 -0.016531" rpy="0 0 0"/>
    </inertial>
    <collision>
      <origin xyz="0.08 0 0" rpy="0 0 0"/>
      <geometry>
        <sphere radius="0.06"/>
      </geometry>
    </collision>
    <collision>
      <origin xyz="0.2 0 0" rpy="0 0 0"/>
      <geometry>
        <sphere radius="0.055"/>
      </geometry>
    </collision>
  </link>

  <link name="AR5-5_07L-W4C4A2_link4">
    <inertial>
      <mass value="1.234"/>
      <inertia ixx="0.00389590" ixy="-0.00004577" ixz="-0.00017280" iyy="0.00308657" iyz="0.00046679" izz="0.00188364"/>
      <origin xyz="-0.007826 -0.004207 0.073404" rpy="0 0 0"/>
    </inertial>
    <collision>
      <origin xyz="0 0 0.04" rpy="0 0 0"/>
      <geometry>
        <sphere radius="0.05"/>
      </geometry>
    </collision>
    <collision>
      <origin xyz="0 0 0.12" rpy="0 0 0"/>
      <geometry>
        <sphere radius="0.045"/>
      </geometry>
    </collision>
  </link>

  <link name="AR5-5_07L-W4C4A2_link5">
    <inertial>
      <mass value="1.329"/>
      <inertia ixx="0.00281562" ixy="0.00001782" ixz="0.00001650" iyy="0.00221084" iyz="0.00002100" izz="0.00182169"/>
      <origin xyz="0.000284 0.001651 -0.084133" rpy="0 0 0"/>
    </inertial>
    <collision>
      <origin xyz="0 0 -0.06" rpy="0 0 0"/>
      <geometry>
        <sphere radius="0.065"/>
      </geometry>
    </collision>
    <collision>
      <origin xyz="0 0 -0.16" rpy="0 0 0"/>
      <geometry>
        <sphere radius="0.055"/>
      </geometry>
    </collision>
  </link>

  <link name="AR5-5_07L-W4C4A2_link6">
    <inertial>
      <mass value="0.93"/>
      <inertia ixx="0.00072078" ixy="-0.00000217" ixz="0.00000108" iyy="0.00085153" iyz="0.00000048" izz="0.00090205"/>
      <origin xyz="0.005406 0.000612 0" rpy="0 0 0"/>
    </inertial>
    <collision>
      <origin xyz="0.01 0 0" rpy="0 0 0"/>
      <geometry>
        <sphere radius="0.038"/>
      </geometry>
    </collision>
  </link>

  <link name="AR5-5_07L-W4C4A2_link7">
    <inertial>
      <mass value="0.33"/>
      <inertia ixx="0.00051942" ixy="-0.00000052" ixz="0.00003721" iyy="0.00079132" iyz="0.00000265" izz="0.00045886"/>
      <origin xyz="-0.00277 0.000316 0.054881" rpy="0 0 0"/>
    </inertial>
    <collision>
      <origin xyz="0 0 0.03" rpy="0 0 0"/>
      <geometry>
        <sphere radius="0.042"/>
      </geometry>
    </collision>
    <collision>
      <origin xyz="0 0 0.09" rpy="0 0 0"/>
      <geometry>
        <sphere radius="0.032"/>
      </geometry>
    </collision>
  </link>

  <link name="AR5-5_07L-W4C4A2_tcp">
    <inertial>
      <mass value="0.001"/>
      <inertia ixx="1e-9" ixy="0" ixz="0" iyy="1e-9" iyz="0" izz="1e-9"/>
      <origin xyz="0 0 0" rpy="0 0 0"/>
    </inertial>
  </link>

  <joint name="fixed" type="fixed">
    <parent link="world"/>
    <child link="AR5-5_07L-W4C4A2_base"/>
    <origin xyz="0 0 0" rpy="0 0 0"/>
  </joint>

  <joint name="AR5-5_07L-W4C4A2_joint_1" type="revolute">
    <parent link="AR5-5_07L-W4C4A2_base"/>
    <child link="AR5-5_07L-W4C4A2_link1"/>
    <limit effort="108" lower="-3.1067" upper="3.1067" velocity="3.0543261909900763"/>
    <axis xyz="0 0 1"/>
    <origin xyz="0 0 0" rpy="0 0 0"/>
  </joint>

  <joint name="AR5-5_07L-W4C4A2_joint_2" type="revolute">
    <parent link="AR5-5_07L-W4C4A2_link1"/>
    <child link="AR5-5_07L-W4C4A2_link2"/>
    <limit effort="108" lower="-2.0944" upper="2.0944" velocity="3.0543261909900763"/>
    <axis xyz="0 1 0"/>
    <origin xyz="0 0 0.1745" rpy="0 0 0"/>
  </joint>

  <joint name="AR5-5_07L-W4C4A2_joint_3" type="revolute">
    <parent link="AR5-5_07L-W4C4A2_link2"/>
    <child link="AR5-5_07L-W4C4A2_link3"/>
    <limit effort="66" lower="-3.1067" upper="3.1067" velocity="4.71238898038469"/>
    <axis xyz="0 0 1"/>
    <origin xyz="0 0 0.314" rpy="0 0 0"/>
  </joint>

  <joint name="AR5-5_07L-W4C4A2_joint_4" type="revolute">
    <parent link="AR5-5_07L-W4C4A2_link3"/>
    <child link="AR5-5_07L-W4C4A2_link4"/>
    <limit effort="66" lower="-1.0472" upper="2.5307" velocity="5.235987755982989"/>
    <axis xyz="0 1 0"/>
    <origin xyz="0.01 0 0" rpy="0 0 0"/>
  </joint>

  <joint name="AR5-5_07L-W4C4A2_joint_5" type="revolute">
    <parent link="AR5-5_07L-W4C4A2_link4"/>
    <child link="AR5-5_07L-W4C4A2_link5"/>
    <limit effort="19" lower="-3.1067" upper="3.1067" velocity="4.1887902047863905"/>
    <axis xyz="0 0 1"/>
    <origin xyz="-0.01 0 0.272" rpy="0 0 0"/>
  </joint>

  <joint name="AR5-5_07L-W4C4A2_joint_6" type="revolute">
    <parent link="AR5-5_07L-W4C4A2_link5"/>
    <child link="AR5-5_07L-W4C4A2_link6"/>
    <limit effort="19" lower="-1.0472" upper="1.0472" velocity="4.1887902047863905"/>
    <axis xyz="0 1 0"/>
    <origin xyz="0 0 0" rpy="0 0 0"/>
  </joint>

  <joint name="AR5-5_07L-W4C4A2_joint_7" type="revolute">
    <parent link="AR5-5_07L-W4C4A2_link6"/>
    <child link="AR5-5_07L-W4C4A2_link7"/>
    <limit effort="19" lower="-1.0472" upper="1.0472" velocity="4.1887902047863905"/>
    <axis xyz="1 0 0"/>
    <origin xyz="0 0 0" rpy="0 0 0"/>
  </joint>

  <joint name="AR5-5_07L-W4C4A2_tcp_joint" type="fixed">
    <parent link="AR5-5_07L-W4C4A2_link7"/>
    <child link="AR5-5_07L-W4C4A2_tcp"/>
    <origin xyz="0 0 0.097" rpy="0 0 0"/>
  </joint>
</robot>
