<?xml version="1.0" encoding="utf-8"?>
<!-- This URDF was automatically created by SolidWorks to URDF Exporter! Originally created by Stephen Brawner (brawner@gmail.com) 
     Commit Version: 1.6.0-1-g15f4949  Build Version: 1.6.7594.29634
     For more information, please see http://wiki.ros.org/sw_urdf_exporter -->
<robot
  name="nexus-arm">
  <link
    name="base_link">
    <inertial>
      <origin
        xyz="0.00155409 -0.00036544 0.0688395"
        rpy="0 0 0" />
      <mass
        value="0.95628283" />
      <inertia
        ixx="0.00207332"
        ixy="-1.672e-05"
        ixz="1.199e-05"
        iyy="0.00216568"
        iyz="-1.92e-06"
        izz="0.00088767" />
    </inertial>
    <visual>
      <origin
        xyz="0 0 0"
        rpy="0 0 0" />
      <geometry>
        <mesh
          filename="package://Tele-arm-right.SLDASM/meshes/base_link.STL" />
      </geometry>
      <material
        name="">
        <color
          rgba="0.752941176470588 0.752941176470588 0.752941176470588 1" />
      </material>
    </visual>
    <collision>
      <origin
        xyz="0 0 0"
        rpy="0 0 0" />
      <geometry>
        <mesh
          filename="package://Tele-arm-right.SLDASM/meshes/base_link.STL" />
      </geometry>
    </collision>
  </link>
  <link
    name="link1_Link">
    <inertial>
      <origin
        xyz="-0.00016706 -0.01517284 0.03109056"
        rpy="0 0 0" />
      <mass
        value="0.08712006" />
      <inertia
        ixx="8.047e-05"
        ixy="-1.1e-07"
        ixz="-1.8e-07"
        iyy="7.463e-05"
        iyz="-2.499e-05"
        izz="5.083e-05" />
    </inertial>
    <visual>
      <origin
        xyz="0 0 0"
        rpy="0 0 0" />
      <geometry>
        <mesh
          filename="package://Tele-arm-right.SLDASM/meshes/link1_Link.STL" />
      </geometry>
      <material
        name="">
        <color
          rgba="0.752941176470588 0.752941176470588 0.752941176470588 1" />
      </material>
    </visual>
    <collision>
      <origin
        xyz="0 0 0"
        rpy="0 0 0" />
      <geometry>
        <mesh
          filename="package://Tele-arm-right.SLDASM/meshes/link1_Link.STL" />
      </geometry>
    </collision>
  </link>
  <joint
    name="link1_Joint"
    type="revolute">
    <origin
      xyz="0 0 0.13305"
      rpy="0 0 0" />
    <parent
      link="base_link" />
    <child
      link="link1_Link" />
    <axis
      xyz="0 0 1" />
    <limit
      lower="-1.5708"
      upper="1.5708"
      effort="9"
      velocity="3.77" />
  </joint>
  <link
    name="link2_Link">
    <inertial>
      <origin
        xyz="0.00106133 0.02987296 0.0650682"
        rpy="0 0 0" />
      <mass
        value="0.85624673" />
      <inertia
        ixx="0.00390267"
        ixy="2.025e-05"
        ixz="-1.5e-06"
        iyy="0.00383255"
        iyz="-1.83e-06"
        izz="0.00044701" />
    </inertial>
    <visual>
      <origin
        xyz="0 0 0"
        rpy="0 0 0" />
      <geometry>
        <mesh
          filename="package://Tele-arm-right.SLDASM/meshes/link2_Link.STL" />
      </geometry>
      <material
        name="">
        <color
          rgba="0.752941176470588 0.752941176470588 0.752941176470588 1" />
      </material>
    </visual>
    <collision>
      <origin
        xyz="0 0 0"
        rpy="0 0 0" />
      <geometry>
        <mesh
          filename="package://Tele-arm-right.SLDASM/meshes/link2_Link.STL" />
      </geometry>
    </collision>
  </link>
  <joint
    name="link2_Joint"
    type="revolute">
    <origin
      xyz="0 -0.026125 0.06"
      rpy="0 0 0" />
    <parent
      link="link1_Link" />
    <child
      link="link2_Link" />
    <axis
      xyz="0 1 0" />
    <limit
      lower="-1.2217"
      upper="0.6981"
      effort="9"
      velocity="3.77" />
  </joint>
  <link
    name="link3_Link">
    <inertial>
      <origin
        xyz="-0.06838837 0.0211209 -1.053e-05"
        rpy="0 0 0" />
      <mass
        value="0.25492132" />
      <inertia
        ixx="0.0001121"
        ixy="-7.509e-05"
        ixz="-6.1e-07"
        iyy="0.00032853"
        iyz="4.4e-07"
        izz="0.000347" />
    </inertial>
    <visual>
      <origin
        xyz="0 0 0"
        rpy="0 0 0" />
      <geometry>
        <mesh
          filename="package://Tele-arm-right.SLDASM/meshes/link3_Link.STL" />
      </geometry>
      <material
        name="">
        <color
          rgba="0.752941176470588 0.752941176470588 0.752941176470588 1" />
      </material>
    </visual>
    <collision>
      <origin
        xyz="0 0 0"
        rpy="0 0 0" />
      <geometry>
        <mesh
          filename="package://Tele-arm-right.SLDASM/meshes/link3_Link.STL" />
      </geometry>
    </collision>
  </link>
  <joint
    name="link3_Joint"
    type="revolute">
    <origin
      xyz="0 0 0.13"
      rpy="0 0 0" />
    <parent
      link="link2_Link" />
    <child
      link="link3_Link" />
    <axis
      xyz="0 1 0" />
    <limit
      lower="-0.7854"
      upper="1.3963"
      effort="9"
      velocity="3.77" />
  </joint>
  <link
    name="link4_Link">
    <inertial>
      <origin
        xyz="-0.11293039 -1.751e-05 -0.0697614"
        rpy="0 0 0" />
      <mass
        value="0.29280428" />
      <inertia
        ixx="0.00033041"
        ixy="-1.35e-06"
        ixz="0.00035344"
        iyy="0.00120202"
        iyz="-4.9e-07"
        izz="0.00096285" />
    </inertial>
    <visual>
      <origin
        xyz="0 0 0"
        rpy="0 0 0" />
      <geometry>
        <mesh
          filename="package://Tele-arm-right.SLDASM/meshes/link4_Link.STL" />
      </geometry>
      <material
        name="">
        <color
          rgba="0.752941176470588 0.752941176470588 0.752941176470588 1" />
      </material>
    </visual>
    <collision>
      <origin
        xyz="0 0 0"
        rpy="0 0 0" />
      <geometry>
        <mesh
          filename="package://Tele-arm-right.SLDASM/meshes/link4_Link.STL" />
      </geometry>
    </collision>
  </link>
  <joint
    name="link4_Joint"
    type="revolute">
    <origin
      xyz="-0.09 0.026125 0"
      rpy="0 0 0" />
    <parent
      link="link3_Link" />
    <child
      link="link4_Link" />
    <axis
      xyz="1 0 0" />
    <limit
      lower="-2.7925"
      upper="2.7925"
      effort="0.8"
      velocity="15.708" />
  </joint>
  <link
    name="link5_Link">
    <inertial>
      <origin
        xyz="-0.02504135 -0.07793003 0.0603572"
        rpy="0 0 0" />
      <mass
        value="0.26337905" />
      <inertia
        ixx="0.00050495"
        ixy="6.642e-05"
        ixz="-7.395e-05"
        iyy="0.00028753"
        iyz="-0.00016153"
        izz="0.00035658" />
    </inertial>
    <visual>
      <origin
        xyz="0 0 0"
        rpy="0 0 0" />
      <geometry>
        <mesh
          filename="package://Tele-arm-right.SLDASM/meshes/link5_Link.STL" />
      </geometry>
      <material
        name="">
        <color
          rgba="0.75294 0.75294 0.75294 1" />
      </material>
    </visual>
    <collision>
      <origin
        xyz="0 0 0"
        rpy="0 0 0" />
      <geometry>
        <mesh
          filename="package://Tele-arm-right.SLDASM/meshes/link5_Link.STL" />
      </geometry>
    </collision>
  </link>
  <joint
    name="link5_Joint"
    type="revolute">
    <origin
      xyz="-0.149385325410789 0 -0.0739103626009013"
      rpy="0 0 0" />
    <parent
      link="link4_Link" />
    <child
      link="link5_Link" />
    <axis
      xyz="-0.38268343236509 0 0.923879532511287" />
    <limit
      lower="-1.3526"
      upper="4.2324"
      effort="0.8"
      velocity="15.708" />
  </joint>
  <link
    name="link6_Link">
    <inertial>
      <origin
        xyz="0.01624066 0.14984587 0.00819943"
        rpy="0 0 0" />
      <mass
        value="0.35623656" />
      <inertia
        ixx="0.00137132"
        ixy="0.00019798"
        ixz="2.494e-05"
        iyy="0.00025926"
        iyz="9.527e-05"
        izz="0.00142119" />
    </inertial>
    <visual>
      <origin
        xyz="0 0 0"
        rpy="0 0 0" />
      <geometry>
        <mesh
          filename="package://Tele-arm-right.SLDASM/meshes/link6_Link.STL" />
      </geometry>
      <material
        name="">
        <color
          rgba="0.752941176470588 0.752941176470588 0.752941176470588 1" />
      </material>
    </visual>
    <collision>
      <origin
        xyz="0 0 0"
        rpy="0 0 0" />
      <geometry>
        <mesh
          filename="package://Tele-arm-right.SLDASM/meshes/link6_Link.STL" />
      </geometry>
    </collision>
  </link>
  <joint
    name="link6_Joint"
    type="revolute">
    <origin
      xyz="-0.0306146745892096 -0.0800000000000015 0.0739103626008975"
      rpy="0 0 0" />
    <parent
      link="link5_Link" />
    <child
      link="link6_Link" />
    <axis
      xyz="0 1 0" />
    <limit
      lower="-3.9706"
      upper="1.6144"
      effort="0.8"
      velocity="15.708" />
  </joint>
  <link
    name="gripper_Link">
    <inertial>
      <origin
        xyz="0.0134519 -0.02525769 -0.00940157"
        rpy="0 0 0" />
      <mass
        value="0.01788063" />
      <inertia
        ixx="9.06e-06"
        ixy="3.44e-06"
        ixz="1.61e-06"
        iyy="4.67e-06"
        iyz="-3.04e-06"
        izz="9.91e-06" />
    </inertial>
    <visual>
      <origin
        xyz="0 0 0"
        rpy="0 0 0" />
      <geometry>
        <mesh
          filename="package://Tele-arm-right.SLDASM/meshes/gripper_Link.STL" />
      </geometry>
      <material
        name="">
        <color
          rgba="0.22353 0.22353 0.22353 1" />
      </material>
    </visual>
    <collision>
      <origin
        xyz="0 0 0"
        rpy="0 0 0" />
      <geometry>
        <mesh
          filename="package://Tele-arm-right.SLDASM/meshes/gripper_Link.STL" />
      </geometry>
    </collision>
  </link>
  <joint
    name="gripper_Joint"
    type="revolute">
    <origin
      xyz="0.0244 0.181 0.01895"
      rpy="0 0 0" />
    <parent
      link="link6_Link" />
    <child
      link="gripper_Link" />
    <axis
      xyz="0 0 1" />
    <limit
      lower="-0.3491"
      upper="0"
      effort="0.8"
      velocity="15.708" />
  </joint>
  <link
    name="force_Link">
    <inertial>
      <origin
        xyz="3.99680288865056E-15 -5.18629974520184E-15 1.72084568816899E-15"
        rpy="0 0 0" />
      <mass
        value="0.00271300000000001" />
      <inertia
        ixx="4.5216666666667E-08"
        ixy="1.83704223536859E-24"
        ixz="-3.70552863678302E-23"
        iyy="4.5216666666667E-08"
        iyz="-7.38046511500889E-25"
        izz="4.52166666666669E-08" />
    </inertial>
    <visual>
      <origin
        xyz="0 0 0"
        rpy="0 0 0" />
      <geometry>
        <mesh
          filename="package://Tele-arm-right.SLDASM(1)/meshes/force_Link.STL" />
      </geometry>
      <material
        name="">
        <color
          rgba="0.792156862745098 0.819607843137255 0.933333333333333 1" />
      </material>
    </visual>
    <collision>
      <origin
        xyz="0 0 0"
        rpy="0 0 0" />
      <geometry>
        <mesh
          filename="package://Tele-arm-right.SLDASM(1)/meshes/force_Link.STL" />
      </geometry>
    </collision>
  </link>
  <joint
    name="force_Joint"
    type="fixed">
    <origin
      xyz="0 0.0799999999999974 0"
      rpy="0 0 0" />
    <parent
      link="link6_Link" />
    <child
      link="force_Link" />
    <axis
      xyz="0 0 0" />
  </joint>
</robot>
