<?xml version='1.0' encoding='utf-8'?>
<mujoco model="AR5-5_07L-W4C4A2">
  <compiler angle="radian" meshdir="../meshes" />
  <!-- 控制律测试：连杆 geom 接触摩擦置零（滑动/扭转/滚动）。恢复：删本段 default，并恢复各 joint 的 damping/frictionloss -->
  <default>
    <geom friction="0 0 0" />
  </default>
  <asset>
    <mesh name="AR5-5_07L-W4C4A2_base" content_type="model/stl" file="AR5-5_07L-W4C4A2_base.stl" scale="0.001 0.001 0.001" />
    <mesh name="AR5-5_07L-W4C4A2_link1" content_type="model/stl" file="AR5-5_07L-W4C4A2_link1.stl" scale="0.001 0.001 0.001" />
    <mesh name="AR5-5_07L-W4C4A2_link2" content_type="model/stl" file="AR5-5_07L-W4C4A2_link2.stl" scale="0.001 0.001 0.001" />
    <mesh name="AR5-5_07L-W4C4A2_link3" content_type="model/stl" file="AR5-5_07L-W4C4A2_link3.stl" scale="0.001 0.001 0.001" />
    <mesh name="AR5-5_07L-W4C4A2_link4" content_type="model/stl" file="AR5-5_07L-W4C4A2_link4.stl" scale="0.001 0.001 0.001" />
    <mesh name="AR5-5_07L-W4C4A2_link5" content_type="model/stl" file="AR5-5_07L-W4C4A2_link5.stl" scale="0.001 0.001 0.001" />
    <mesh name="AR5-5_07L-W4C4A2_link6" content_type="model/stl" file="AR5-5_07L-W4C4A2_link6.stl" scale="0.001 0.001 0.001" />
    <mesh name="AR5-5_07L-W4C4A2_link7" content_type="model/stl" file="AR5-5_07L-W4C4A2_link7.stl" scale="0.001 0.001 0.001" />
  </asset>
  <worldbody>
    <!-- 连杆 mesh：contype=2 conaffinity=1 → 连杆间 (2&1)=0 不自碰；与地面默认 1/1 仍 (1&1)≠0 可碰地 -->
    <geom type="mesh" rgba="1 1 1 1" mesh="AR5-5_07L-W4C4A2_base" contype="0" conaffinity="0" density="0" group="1" />
    <body name="AR5-5_07L-W4C4A2_link1">
      <inertial pos="1e-06 -0.000621 0.167909" quat="0.999997 -0.000531118 -0.00163028 0.00193396" mass="2.683" diaginertia="0.00493674 0.00452343 0.00432909" />
      <!-- 原 damping="5.4" frictionloss="1.08" -->
      <!-- armature = rotor_inertia*N² (kg·m² @ joint)，与 robot_controller arm_control_ar5.yaml motor_params 一致 -->
      <joint name="AR5-5_07L-W4C4A2_joint_1" pos="0 0 0" axis="0 0 1" range="-3.1067 3.1067" actuatorfrcrange="-108 108" damping="0" frictionloss="0" armature="1.756944" />
      <geom type="mesh" rgba="1 1 1 1" mesh="AR5-5_07L-W4C4A2_link1" contype="2" conaffinity="1" />
      <body name="AR5-5_07L-W4C4A2_link2" pos="0 0 0.1745">
        <inertial pos="-2e-05 -0.003081 0.102986" quat="0.99742 0.0717838 3.70567e-06 0.000805645" mass="2.3" diaginertia="0.0115191 0.0100527 0.00423304" />
        <!-- 原 damping="5.4" frictionloss="1.08" -->
        <joint name="AR5-5_07L-W4C4A2_joint_2" pos="0 0 0" axis="0 1 0" range="-2.0944 2.0944" actuatorfrcrange="-108 108" damping="0" frictionloss="0" armature="1.756944" />
        <geom type="mesh" rgba="1 1 1 1" mesh="AR5-5_07L-W4C4A2_link2" contype="2" conaffinity="1" />
        <body name="AR5-5_07L-W4C4A2_link3" pos="0 0 0.314">
          <inertial pos="0.007097 -0.000659 -0.016531" quat="0.997475 0.00666453 -0.0689001 0.0158749" mass="1.862" diaginertia="0.00524691 0.00470445 0.00261743" />
          <!-- 原 damping="3.3" frictionloss="0.66" -->
          <joint name="AR5-5_07L-W4C4A2_joint_3" pos="0 0 0" axis="0 0 1" range="-3.1067 3.1067" actuatorfrcrange="-66 66" damping="0" frictionloss="0" armature="0.7084" />
          <geom type="mesh" rgba="1 1 1 1" mesh="AR5-5_07L-W4C4A2_link3" contype="2" conaffinity="1" />
          <body name="AR5-5_07L-W4C4A2_link4" pos="0.01 0 0">
            <inertial pos="-0.007826 -0.004207 0.073404" quat="0.983995 0.159096 0.04534 -0.0662269" mass="1.234" diaginertia="0.00392058 0.00323193 0.0017136" />
            <!-- 原 damping="3.3" frictionloss="0.66" -->
            <joint name="AR5-5_07L-W4C4A2_joint_4" pos="0 0 0" axis="0 1 0" range="-1.0472 2.5307" actuatorfrcrange="-66 66" damping="0" frictionloss="0" armature="0.7084" />
            <geom type="mesh" rgba="1 1 1 1" mesh="AR5-5_07L-W4C4A2_link4" contype="2" conaffinity="1" />
            <body name="AR5-5_07L-W4C4A2_link5" pos="-0.01 0 0.272">
              <inertial pos="0.000284 0.001651 -0.084133" quat="0.999502 0.0263782 -0.00820774 0.0152264" mass="1.329" diaginertia="0.00281644 0.00221139 0.00182032" />
              <!-- 原 damping="0.95" frictionloss="0.19" -->
              <joint name="AR5-5_07L-W4C4A2_joint_5" pos="0 0 0" axis="0 0 1" range="-3.1067 3.1067" actuatorfrcrange="-19 19" damping="0" frictionloss="0" armature="0.1744" />
              <geom type="mesh" rgba="1 1 1 1" mesh="AR5-5_07L-W4C4A2_link5" contype="2" conaffinity="1" />
              <body name="AR5-5_07L-W4C4A2_link6">
                <inertial pos="0.005406 0.000612 -3.9e-05" quat="-0.00263042 0.709166 0.00913489 0.704977" mass="0.93" diaginertia="0.000902061 0.000851562 0.000720737" />
                <!-- 原 damping="0.95" frictionloss="0.19" -->
                <joint name="AR5-5_07L-W4C4A2_joint_6" pos="0 0 0" axis="0 1 0" range="-1.0472 1.0472" actuatorfrcrange="-19 19" damping="0" frictionloss="0" armature="0.1744" />
                <geom type="mesh" rgba="1 1 1 1" mesh="AR5-5_07L-W4C4A2_link6" contype="2" conaffinity="1" />
                <body name="AR5-5_07L-W4C4A2_link7">
                  <inertial pos="-0.00277 0.000316 0.054881" quat="0.690089 -0.152839 -0.158402 0.689439" mass="0.33" diaginertia="0.000791341 0.000537112 0.000441147" />
                  <!-- 原 damping="0.95" frictionloss="0.19" -->
                  <joint name="AR5-5_07L-W4C4A2_joint_7" pos="0 0 0" axis="1 0 0" range="-1.0472 1.0472" actuatorfrcrange="-19 19" damping="0" frictionloss="0" armature="0.1744" />
                  <geom type="mesh" rgba="1 1 1 1" mesh="AR5-5_07L-W4C4A2_link7" contype="2" conaffinity="1" />
                </body>
              </body>
            </body>
          </body>
        </body>
      </body>
    </body>
  </worldbody>
</mujoco>
