<?xml version='1.0' encoding='utf-8'?>
<mujoco model="fr3v2_1">
  <compiler angle="radian" meshdir="../meshes" />
  <asset>
    <mesh name="fr3v2_1_link0" content_type="model/stl" file="fr3v2_1_link0.stl" />
    <mesh name="fr3v2_1_link1" content_type="model/stl" file="fr3v2_1_link1.stl" />
    <mesh name="fr3v2_1_link2" content_type="model/stl" file="fr3v2_1_link2.stl" />
    <mesh name="fr3v2_1_link3" content_type="model/stl" file="fr3v2_1_link3.stl" />
    <mesh name="fr3v2_1_link4" content_type="model/stl" file="fr3v2_1_link4.stl" />
    <mesh name="fr3v2_1_link5" content_type="model/stl" file="fr3v2_1_link5.stl" />
    <mesh name="fr3v2_1_link6" content_type="model/stl" file="fr3v2_1_link6.stl" />
    <mesh name="fr3v2_1_link7" content_type="model/stl" file="fr3v2_1_link7.stl" />
    <mesh name="fr3v2_1_hand" content_type="model/stl" file="fr3v2_1_hand.stl" />
  </asset>
  <worldbody>
    <geom name="fr3v2_1_link0_collision" type="mesh" mesh="fr3v2_1_link0" contype="0" conaffinity="0" density="0" group="1" />
    <body name="fr3v2_1_link1" pos="0 0 0.333">
      <inertial pos="-0.00458 0.027016 -0.0618" quat="0.989811 0.110789 0.00992127 0.0888923" mass="2.4377" diaginertia="0.0233003 0.0222611 0.00463865" />
      <joint name="fr3v2_1_joint1" pos="0 0 0" axis="0 0 1" range="-2.90074 2.90074" actuatorfrcrange="-87 87" damping="0.003" frictionloss="0.2" armature="0.087" />
      <geom name="fr3v2_1_link1_collision" type="mesh" mesh="fr3v2_1_link1" contype="1" conaffinity="15" density="0" group="0" />
      <body name="fr3v2_1_link2" quat="0.707107 -0.707107 0 0">
        <inertial pos="-0.01063 -0.184739 -0.010479" quat="0.644329 0.758803 -0.0323054 0.0895283" mass="2.2375" diaginertia="0.0192001 0.0173406 0.0052593" />
        <joint name="fr3v2_1_joint2" pos="0 0 0" axis="0 0 1" range="-1.83609 1.83609" actuatorfrcrange="-87 87" damping="0.003" frictionloss="0.2" armature="0.087" />
        <geom name="fr3v2_1_link2_collision" type="mesh" mesh="fr3v2_1_link2" contype="1" conaffinity="15" density="0" group="0" />
        <body name="fr3v2_1_link3" pos="0 -0.316 0" quat="0.707107 0.707107 0 0">
          <inertial pos="0.091995 0.023003 0.047348" quat="0.877348 -0.0280595 -0.265819 0.398514" mass="2.19638" diaginertia="0.0146052 0.0104212 0.00447362" />
          <joint name="fr3v2_1_joint3" pos="0 0 0" axis="0 0 1" range="-2.90074 2.90074" actuatorfrcrange="-87 87" damping="0.003" frictionloss="0.2" armature="0.087" />
          <geom name="fr3v2_1_link3_collision" type="mesh" mesh="fr3v2_1_link3" contype="1" conaffinity="15" density="0" group="0" />
          <body name="fr3v2_1_link4" pos="0.0825 0 0" quat="0.707107 0.707107 0 0">
            <inertial pos="-0.084334 0.096836 0.006248" quat="0.725019 0.567552 -0.379628 -0.0900828" mass="2.18642" diaginertia="0.0126388 0.00973606 0.00442618" />
            <joint name="fr3v2_1_joint4" pos="0 0 0" axis="0 0 1" range="-3.07702 -0.116937" actuatorfrcrange="-87 87" damping="0.003" frictionloss="0.2" armature="0.087" />
            <geom name="fr3v2_1_link4_collision" type="mesh" mesh="fr3v2_1_link4" contype="1" conaffinity="15" density="0" group="0" />
            <body name="fr3v2_1_link5" pos="-0.0825 0.384 0" quat="0.707107 -0.707107 0 0">
              <inertial pos="3.9e-05 0.011821 -0.054936" quat="0.993747 -0.0901363 0.0101557 0.0651102" mass="2.19078" diaginertia="0.0318998 0.0305191 0.0038801" />
              <joint name="fr3v2_1_joint5" pos="0 0 0" axis="0 0 1" range="-2.8763 2.8763" actuatorfrcrange="-12 12" damping="0.003" frictionloss="0.2" armature="0.012" />
              <geom name="fr3v2_1_link5_collision" type="mesh" mesh="fr3v2_1_link5" contype="1" conaffinity="15" density="0" group="0" />
              <body name="fr3v2_1_link6" quat="0.707107 0.707107 0 0">
                <inertial pos="0.069627 -0.016716 -0.037235" quat="-0.141552 0.574736 0.130817 0.795317" mass="1.58358" diaginertia="0.0047496 0.0041461 0.0024043" />
                <joint name="fr3v2_1_joint6" pos="0 0 0" axis="0 0 1" range="0.439823 4.62163" actuatorfrcrange="-12 12" damping="0.003" frictionloss="0.2" armature="0.012" />
                <geom name="fr3v2_1_link6_collision" type="mesh" mesh="fr3v2_1_link6" contype="1" conaffinity="15" density="0" group="0" />
                <body name="fr3v2_1_link7" pos="0.088 0 0" quat="0.707107 0.707107 0 0">
                  <inertial pos="-0.00753387 -0.0412165 0.043312" quat="0.570344 0.81934 0.00226748 0.0581812" mass="1.35309" diaginertia="0.00722602 0.00680499 0.00153297" />
                  <joint name="fr3v2_1_joint7" pos="0 0 0" axis="0 0 1" range="-3.05083 3.05083" actuatorfrcrange="-12 12" damping="0.003" frictionloss="0.2" armature="0.012" />
                  <geom name="fr3v2_1_link7_collision" type="mesh" mesh="fr3v2_1_link7" contype="1" conaffinity="15" density="0" group="0" />
                  <geom name="fr3v2_1_hand_collision" pos="0 0 0.107" quat="0.92388 0 0 -0.382683" type="mesh" mesh="fr3v2_1_hand" contype="1" conaffinity="15" density="0" group="0" />
                  <body name="fr3v2_1_leftfinger" pos="0 0 0.1654" quat="0.92388 0 0 -0.382683">
                    <inertial pos="0 0.015285 0.0219675" quat="0.705067 -0.0536699 0.0536699 0.705067" mass="0.0291" diaginertia="8.69232e-06 8.49e-06 1.60768e-06" />
                    <joint name="fr3v2_1_finger_joint1" pos="0 0 0" axis="0 1 0" type="slide" range="0 0.04" actuatorfrcrange="-100 100" damping="0.3" frictionloss="2.0" armature="1.0" />
                    <geom size="0.011 0.0075 0.01" pos="0 0.0185 0.011" type="box" />
                    <geom size="0.011 0.0044 0.0019" pos="0 0.0068 0.0022" type="box" />
                    <geom size="0.00875 0.0035 0.01175" pos="0 0.0159 0.02835" quat="0.965926 0.258819 0 0" type="box" />
                    <geom size="0.00875 0.0076 0.00925" pos="0 0.00758 0.04525" type="box" />
                  </body>
                  <body name="fr3v2_1_rightfinger" pos="0 0 0.1654" quat="0.382683 0 0 0.92388">
                    <inertial pos="0 0.015285 0.0219675" quat="0.705067 -0.0536699 0.0536699 0.705067" mass="0.0291" diaginertia="8.69232e-06 8.49e-06 1.60768e-06" />
                    <joint name="fr3v2_1_finger_joint2" pos="0 0 0" axis="0 1 0" type="slide" range="0 0.04" actuatorfrcrange="-100 100" damping="0.3" frictionloss="2.0" armature="1.0" />
                    <geom size="0.011 0.0075 0.01" pos="0 0.0185 0.011" type="box" />
                    <geom size="0.011 0.0044 0.0019" pos="0 0.0068 0.0022" type="box" />
                    <geom size="0.00875 0.0035 0.01175" pos="0 0.0159 0.02835" quat="0 0 -0.258819 0.965926" type="box" />
                    <geom size="0.00875 0.0076 0.00925" pos="0 0.00758 0.04525" type="box" />
                  </body>
                </body>
              </body>
            </body>
          </body>
        </body>
      </body>
    </body>
  </worldbody>
</mujoco>
