<?xml version='1.0' encoding='utf-8'?>
<mujoco model="y1">
  <compiler angle="radian" meshdir="../meshes" />
  <asset>
    <mesh name="base_link" content_type="model/stl" file="base_link.STL" />
    <mesh name="link1" content_type="model/stl" file="link1.STL" />
    <mesh name="link2" content_type="model/stl" file="link2.STL" />
    <mesh name="link3" content_type="model/stl" file="link3.STL" />
    <mesh name="link4" content_type="model/stl" file="link4.STL" />
    <mesh name="link5" content_type="model/stl" file="link5.STL" />
    <mesh name="link6" content_type="model/stl" file="link6.STL" />
    <mesh name="gripper_base" content_type="model/stl" file="gripper_base.STL" />
    <mesh name="link7" content_type="model/stl" file="link7.STL" />
    <mesh name="link8" content_type="model/stl" file="link8.STL" />
  </asset>
  <worldbody>
    <geom type="mesh" rgba="0.898039 0.917647 0.929412 1" mesh="base_link" contype="0" conaffinity="0" density="0" group="1" />
    <body name="link1" pos="0 0 0.06675" quat="1 0 0 0">
      <inertial pos="0.000681167 -0.000462329 0.0457749" mass="0.465086" diaginertia="0.000229226849289421 0.000349392243512686 0.000228246849171451" />
      <joint name="joint1" pos="0 0 0" axis="0 0 1" range="-2.79 2.79" actuatorfrcrange="-30 30" />
      <geom type="mesh" rgba="0.898039 0.917647 0.929412 1" mesh="link1" contype="1" conaffinity="15" density="0" group="0" />
      <body name="link2" pos="0.00075 0 0.055" quat="0.707107 0.707107 0 0">
        <inertial pos="-0.188834 -0.00103697 -0.000652233" mass="1.00848" diaginertia="0.000410794336332579 0.0060417092412649 0.00611040782664147" />
        <joint name="joint2" pos="0 0 0" axis="0 0 1" range="-3.14 0" actuatorfrcrange="-100 100" />
        <geom type="mesh" rgba="0.898039 0.917647 0.929412 1" mesh="link2" contype="1" conaffinity="15" density="0" group="0" />
        <body name="link3" pos="-0.28 0 0" quat="1 0 0 0">
          <inertial pos="0.133032 0.0530016 0.000290607" mass="0.839664" diaginertia="0.000602602152841581 0.00179992027196969 0.00208247690008721" />
          <joint name="joint3" pos="0 0 0" axis="0 0 1" range="0 3.14" actuatorfrcrange="-30 30" />
          <geom type="mesh" rgba="0.898039 0.917647 0.929412 1" mesh="link3" contype="1" conaffinity="15" density="0" group="0" />
          <body name="link4" pos="0.215 0.063 0" quat="1 0 0 0">
            <inertial pos="0.0666891 0.0612495 0.00493164" mass="0.455193" diaginertia="0.000176582732613137 0.000211179169445067 0.000207766320179744" />
            <joint name="joint4" pos="0 0 0" axis="0 0 1" range="-2.145 1.413" actuatorfrcrange="-10 10" />
            <geom type="mesh" rgba="0.898039 0.917647 0.929412 1" mesh="link4" contype="1" conaffinity="15" density="0" group="0" />
            <body name="link5" pos="0.08 0.052 0.000249998" quat="0.707107 0.707107 0 0">
              <inertial pos="0.00248531 1.71804e-05 0.0400786" mass="0.373509" diaginertia="0.00016414068497646 0.000150227046495623 0.000141442797294447" />
              <joint name="joint5" pos="0 0 0" axis="0 0 1" range="-1.482 1.482" actuatorfrcrange="-10 10" />
              <geom type="mesh" rgba="0.898039 0.917647 0.929412 1" mesh="link5" contype="1" conaffinity="15" density="0" group="0" />
              <body name="link6" pos="0.0235 0 0.044" quat="0 -1 0 0">
                <inertial pos="0.0108106656274518 0.000127504395052592 0.00016010488602905" mass="0.0724468602058996" diaginertia="3.15031267100887E-05 1.66634761480036E-05 1.66897035808186E-05" />
                <joint name="joint6" pos="0 0 0" axis="1 0 0" range="-2.529 2.529" actuatorfrcrange="-10 10" />
                <geom type="mesh" rgba="0.898039 0.917647 0.929412 1" mesh="link6" contype="1" conaffinity="15" density="0" group="0" />
                <!-- Site 标记：link6 末端执行器位置 -->
                <site name="ee_link6" pos="0 0 0" size="0.01" rgba="1 0 0 0.5" type="sphere" />
                <body name="gripper_base" pos="0.0758 0 0" quat="0.0 0.707106781186548 0.0 0.707106781186548">
                  <inertial pos="-0.00722300540551239 -2.86486663753245E-07 -0.0281150308975901" mass="0.436099620967633" diaginertia="0.000287710583661291 0.000225234897934958 0.000396215714285049" />
                  <geom type="mesh" rgba="0.792157 0.819608 0.933333 1" mesh="gripper_base" contype="1" conaffinity="15" density="0" group="0" />
                  <body name="link7" pos="0 -0.00275 0" quat="0.707106781186548 0 0 -0.707106781186548">
                    <inertial pos="-0.0155281 -0.00524433 0.0238751" mass="0.0661691" diaginertia="1.90679558147809E-05 1.66105397877526E-05 8.26385767759474E-06" />
                    <joint name="joint7" pos="0 0 0" axis="1 0 0" type="slide" range="-0.05 0" actuatorfrcrange="-3 3" />
                    <geom type="mesh" rgba="0.647059 0.619608 0.588235 1" mesh="link7" contype="1" conaffinity="15" density="0" group="0" />
                  </body>
                  <body name="link8" pos="0 0.00275 0" quat="0.707106781186548 0 0 -0.707106781186548">
                    <inertial pos="0.015528 -0.00524433 0.0241082" mass="0.0661691" diaginertia="1.90679558147809E-05 1.66105397877526E-05 8.26385767759474E-06" />
                    <joint name="joint8" pos="0 0 0" axis="1 0 0" type="slide" range="0 0.05" actuatorfrcrange="-3 3" />
                    <geom type="mesh" rgba="0.647059 0.619608 0.588235 1" mesh="link8" contype="1" conaffinity="15" density="0" group="0" />
                  </body>
                </body>
              </body>
            </body>
          </body>
        </body>
      </body>
    </body>
  </worldbody>
</mujoco>

