<?xml version='1.0' encoding='utf-8'?>
<mujoco model="nexus-arm">
  <compiler angle="radian" meshdir="../meshes" />
  <asset>
    <mesh name="base_link" content_type="model/stl" file="base_link.STL" />
    <mesh name="link1_Link" content_type="model/stl" file="link1_Link.STL" />
    <mesh name="link2_Link" content_type="model/stl" file="link2_Link.STL" />
    <mesh name="link3_Link" content_type="model/stl" file="link3_Link.STL" />
    <mesh name="link4_Link" content_type="model/stl" file="link4_Link.STL" />
    <mesh name="link5_Link" content_type="model/stl" file="link5_Link.STL" />
    <mesh name="link6_Link" content_type="model/stl" file="link6_Link.STL" />
    <mesh name="gripper_Link" content_type="model/stl" file="gripper_Link.STL" />
    <mesh name="force_Link" content_type="model/stl" file="force_Link.STL" />
  </asset>
  <worldbody>
    <geom type="mesh" rgba="0.752941 0.752941 0.752941 1" mesh="base_link" contype="0" conaffinity="0" density="0" group="1" />
    <body name="link1_Link" pos="0 0 0.13305">
      <inertial pos="-0.00016706 -0.0151728 0.0310906" quat="0.679816 -0.194949 0.198043 0.678693" mass="0.0871201" diaginertia="9.04087e-05 8.0471e-05 3.50503e-05" />
      <joint name="link1_Joint" pos="0 0 0" axis="0 0 1" range="-1.5708 1.5708" actuatorfrcrange="-9 9" damping="0.45" frictionloss="0.09" armature="0.009" />
      <geom type="mesh" rgba="0.75294 0.75294 0.75294 1" mesh="link1_Link" />
      <body name="link2_Link" pos="0 -0.026125 0.0605">
        <inertial pos="0.00106133 0.029873 0.0650682" quat="0.991439 -0.000238542 0.000248736 0.130574" mass="0.856247" diaginertia="0.0039081 0.00382712 0.000447008" />
        <joint name="link2_Joint" pos="0 0 0" axis="0 1 0" range="-1.2217 0.6981" actuatorfrcrange="-9 9" damping="0.45" frictionloss="0.09" armature="0.009" />
        <geom type="mesh" rgba="0.752941 0.752941 0.752941 1" mesh="link2_Link" />
        <body name="link3_Link" pos="0 0 0.13">
          <inertial pos="-0.0685324 0.021125 9.764e-05" quat="0.375497 0.459771 0.535332 0.600859" mass="0.256533" diaginertia="0.000353452 0.000347868 8.92804e-05" />
          <joint name="link3_Joint" pos="0 0 0" axis="0 1 0" range="-0.7854 1.3963" actuatorfrcrange="-9 9" damping="0.45" frictionloss="0.09" armature="0.009" />
          <geom type="mesh" rgba="0.752941 0.752941 0.752941 1" mesh="link3_Link" />
          <body name="link4_Link" pos="-0.09 0.026125 0">
            <inertial pos="-0.111491 3.179e-05 -0.0691476" quat="0.388407 0.584041 0.604799 0.377167" mass="0.302327" diaginertia="0.00127663 0.00119376 0.000178142" />
            <joint name="link4_Joint" pos="0 0 0" axis="1 0 0" range="-0.6981 2.0944" actuatorfrcrange="-0.8 0.8" damping="0.05" frictionloss="0.01" armature="0.0008" />
            <geom type="mesh" rgba="0.75294 0.75294 0.75294 1" mesh="link4_Link" />
            <body name="link5_Link" pos="-0.149385 0 -0.0739104">
              <inertial pos="-0.0249397 -0.0775073 0.059897" quat="0.789289 0.575046 0.215097 -0.00882033" mass="0.268974" diaginertia="0.000575218 0.000350975 0.000273607" />
              <joint name="link5_Joint" pos="0 0 0" axis="-0.382683 0 0.92388" range="-0.8727 0.8727" actuatorfrcrange="-0.8 0.8" damping="0.05" frictionloss="0.01" armature="0.0008" />
              <geom type="mesh" rgba="0.752941 0.752941 0.752941 1" mesh="link5_Link" />
              <body name="link6_Link" pos="-0.030615 -0.08 0.07391">
                <inertial pos="0.0179642 0.149509 -1.51109e-05" quat="0.446525 0.549666 -0.44602 0.547311" mass="0.378422" diaginertia="0.0013142 0.00121891 0.000247145" />
                <joint name="link6_Joint" pos="0 0 0" axis="0 1 0" range="-0.7854 3.1416" actuatorfrcrange="-0.8 0.8" damping="0.05" frictionloss="0.01" armature="0.0008" />
                <geom type="mesh" rgba="0.75294 0.75294 0.75294 1" mesh="link6_Link" />
                <geom pos="0 0.08 0" type="mesh" rgba="0.792157 0.819608 0.933333 1" mesh="force_Link" />
                <site name="ee_link6" pos="0 0.08 0" size="0.01" rgba="1 0 0 0.5" type="sphere" />
                <body name="gripper_Link" pos="0.029809 0.1198 0">
                  <inertial pos="-0.00285473 0.0104286 0" quat="0.562791 0.428096 -0.562791 0.428096" mass="0.00447781" diaginertia="7.9e-07 7.03238e-07 2.36762e-07" />
                  <joint name="gripper_Joint" pos="0 0 0" axis="0.978148 0.20791 0" type="slide" range="0 0.03" actuatorfrcrange="-0.8 0.8" damping="0.08" frictionloss="0.016" armature="0.008" />
                  <geom type="mesh" rgba="1 1 1 1" mesh="gripper_Link" />
                </body>
              </body>
            </body>
          </body>
        </body>
      </body>
    </body>
  </worldbody>
</mujoco>
