<?xml version='1.0' encoding='utf-8'?>
<mujoco model="a2_tabletop">
  <compiler angle="radian" meshdir="../meshes" />
  <asset>
    <mesh name="left_arm_base_link" content_type="model/stl" file="left_arm_base_link.STL" />
    <mesh name="left_arm_link1" content_type="model/stl" file="left_arm_link1.STL" />
    <mesh name="left_arm_link2" content_type="model/stl" file="left_arm_link2.STL" />
    <mesh name="left_arm_link3" content_type="model/stl" file="left_arm_link3.STL" />
    <mesh name="left_arm_link4" content_type="model/stl" file="left_arm_link4.STL" />
    <mesh name="left_arm_link5" content_type="model/stl" file="left_arm_link5.STL" />
    <mesh name="left_arm_link6" content_type="model/stl" file="left_arm_link6.STL" />
    <mesh name="left_arm_link7" content_type="model/stl" file="left_arm_link7.STL" />
    <mesh name="left_gripper_link" content_type="model/stl" file="left_gripper_link.STL" />
    <mesh name="left_gripper_finger_link1" content_type="model/stl" file="left_gripper_finger_link1.STL" />
    <mesh name="left_gripper_finger_link2" content_type="model/stl" file="left_gripper_finger_link2.STL" />
  </asset>
  <worldbody>
    <geom quat="0.499998 0.5 -0.500002 -0.5" type="mesh" rgba="0.82353 0.82353 1 1" mesh="left_arm_base_link" contype="0" conaffinity="0" density="0" group="1" />
    <body name="left_arm_link1" pos="-2.69981e-07 0 0.0735" quat="0.499998 0.5 -0.500002 -0.5">
      <inertial pos="0.00042258 0.074131 7.9156e-05" quat="0.705776 0.708428 0.000383566 -0.00300782" mass="1.135" diaginertia="0.000616038 0.000471359 0.000302583" />
      <joint name="left_arm_joint1" pos="0 0 0" axis="0 1 0" range="-4.4506 1.309" actuatorfrcrange="-55 55" damping="2.75" frictionloss="0.55" armature="0.055" />
      <geom type="mesh" rgba="0.82353 0.82353 1 1" mesh="left_arm_link1" contype="1" conaffinity="15" density="0" group="0" />
      <body name="left_arm_link2" pos="0.025012 0.081265 0">
        <inertial pos="-0.026826 -0.0040392 -0.031835" quat="0.967826 0.24999 -0.0279104 0.00629583" mass="0.92" diaginertia="0.000373948 0.000345466 0.000316696" />
        <joint name="left_arm_joint2" pos="0 0 0" axis="1 0 0" range="-0.1745 3.1416" actuatorfrcrange="-55 55" damping="2.75" frictionloss="0.55" armature="0.055" />
        <geom type="mesh" rgba="0.82353 0.82353 1 1" mesh="left_arm_link2" contype="1" conaffinity="15" density="0" group="0" />
        <body name="left_arm_link3" pos="-0.025012 0 -0.1155">
          <inertial pos="0.0053849 -0.00086892 -0.1126" quat="0.987419 -0.0126124 0.157363 -0.00905809" mass="1.245" diaginertia="0.000765373 0.000738745 0.000331352" />
          <joint name="left_arm_joint3" pos="0 0 0" axis="0 0 1" range="-2.3562 2.3562" actuatorfrcrange="-25 25" damping="1.25" frictionloss="0.25" armature="0.025" />
          <geom type="mesh" rgba="0.82353 0.82353 1 1" mesh="left_arm_link3" contype="1" conaffinity="15" density="0" group="0" />
          <body name="left_arm_link4" pos="0 0.035065 -0.1945">
            <inertial pos="-0.0011018 -0.036243 -0.042164" quat="0.70731 -0.0289938 -0.0395261 0.705202" mass="0.827" diaginertia="0.000197532 0.000139189 0.000101919" />
            <joint name="left_arm_joint4" pos="0 0 0" axis="0 1 0" range="-2.0944 0.3491" actuatorfrcrange="-25 25" damping="1.25" frictionloss="0.25" armature="0.025" />
            <geom type="mesh" rgba="0.82353 0.82353 1 1" mesh="left_arm_link4" contype="1" conaffinity="15" density="0" group="0" />
            <body name="left_arm_link5" pos="0 -0.035065 -0.095">
              <inertial pos="3.7881e-07 -0.0028035 -0.062981" quat="0.997254 -0.074061 2.09046e-05 0.000268168" mass="0.939" diaginertia="0.00070496 0.000677819 0.000322221" />
              <joint name="left_arm_joint5" pos="0 0 0" axis="0 0 1" range="-2.3562 2.3562" actuatorfrcrange="-18 18" damping="0.9" frictionloss="0.18" armature="0.018" />
              <geom type="mesh" rgba="0.82353 0.82353 1 1" mesh="left_arm_link5" contype="1" conaffinity="15" density="0" group="0" />
              <body name="left_arm_link6" pos="0 -0.028 -0.16305">
                <inertial pos="0.0017919 0.027487 0.00025471" quat="0.704102 0.696344 -0.110248 0.0847966" mass="0.527" diaginertia="8.56857e-05 8.24979e-05 8.11804e-05" />
                <joint name="left_arm_joint6" pos="0 0 0" axis="0 1 0" range="-1.0472 1.0472" actuatorfrcrange="-18 18" damping="0.9" frictionloss="0.18" armature="0.018" />
                <geom type="mesh" rgba="0.82353 0.82353 1 1" mesh="left_arm_link6" contype="1" conaffinity="15" density="0" group="0" />
                <body name="left_arm_link7" pos="0.0295 0.028 0">
                  <inertial pos="-0.0111593 0.0917244 -0.0233306" quat="0.311497 0.349545 -0.73699 0.487477" mass="0.43125" diaginertia="0.00334928 0.00332825 0.000153625" />
                  <joint name="left_arm_joint7" pos="0 0 0" axis="1 0 0" range="-1.5708 1.5708" actuatorfrcrange="-18 18" damping="0.9" frictionloss="0.18" armature="0.018" />
                  <geom type="mesh" rgba="0.82353 0.82353 1 1" mesh="left_arm_link7" contype="1" conaffinity="15" density="0" group="0" />
                  <geom pos="-0.0295 0 -0.16065" quat="1 0 0 0" type="mesh" rgba="0.82353 0.82353 1 1" mesh="left_gripper_link" contype="1" conaffinity="15" density="0" group="0" />
                  <body name="left_gripper_finger_link1" pos="-0.0295887 0.013453 -0.19754">
                    <inertial pos="0.0056571 -0.015027 0.01959" quat="0.996815 -0.0588415 0.00751429 0.0532934" mass="0.020196" diaginertia="6.4915e-06 5.75204e-06 2.35776e-06" />
                    <joint name="left_gripper_finger_joint1" pos="0 0 0" axis="0 1 0" type="slide" range="0 0.05" actuatorfrcrange="-100 100" damping="10.0" frictionloss="2.0" armature="1.0" />
                    <geom type="mesh" rgba="0.82353 0.82353 1 1" mesh="left_gripper_finger_link1" contype="1" conaffinity="15" density="0" group="0" />
                  </body>
                  <body name="left_gripper_finger_link2" pos="-0.029411 -0.013453 -0.19754">
                    <inertial pos="-0.0056573 0.015027 0.01959" quat="0.996815 0.0588425 -0.00751885 0.0532936" mass="0.020196" diaginertia="6.4915e-06 5.75204e-06 2.35776e-06" />
                    <joint name="left_gripper_finger_joint2" pos="0 0 0" axis="0 1 0" type="slide" range="-0.05 0" actuatorfrcrange="-100 100" damping="10.0" frictionloss="2.0" armature="1.0" />
                    <geom type="mesh" rgba="0.82353 0.82353 1 1" mesh="left_gripper_finger_link2" contype="1" conaffinity="15" density="0" group="0" />
                  </body>
                </body>
              </body>
            </body>
          </body>
        </body>
      </body>
    </body>
  </worldbody>
</mujoco>
