<?xml version="1.0" encoding="utf-8"?>
<!-- This URDF was automatically created by SolidWorks to URDF Exporter! Originally created by Stephen Brawner (brawner@gmail.com) 
     Commit Version: 1.6.0-4-g7f85cfe  Build Version: 1.6.7995.38578
     For more information, please see http://wiki.ros.org/sw_urdf_exporter -->
<robot
  name="nexus-arm-v15-right">
  <link
    name="base_link">
    <inertial>
      <origin
        xyz="-0.00197698722131881 -0.000492342913379271 0.0500491361473581"
        rpy="0 0 0" />
      <mass
        value="1.33721444591793" />
      <inertia
        ixx="0.000849323768732891"
        ixy="-3.80684496393435E-07"
        ixz="1.28551949125856E-05"
        iyy="0.000797667090311193"
        iyz="-3.52081763779121E-07"
        izz="0.00127090853090879" />
    </inertial>
    <visual>
      <origin
        xyz="0 0 0"
        rpy="0 0 0" />
      <geometry>
        <mesh
          filename="package://Tele-arm-right.SLDASM/meshes/base_link.STL" />
      </geometry>
      <material
        name="">
        <color
          rgba="0.752941176470588 0.752941176470588 0.752941176470588 1" />
      </material>
    </visual>
    <collision>
      <origin
        xyz="0 0 0"
        rpy="0 0 0" />
      <geometry>
        <mesh
          filename="package://Tele-arm-right.SLDASM/meshes/base_link.STL" />
      </geometry>
    </collision>
  </link>
  <link
    name="link1_Link">
    <inertial>
      <origin
        xyz="-5.21242967001577E-05 -0.00593260853459528 0.0304373930218112"
        rpy="0 0 0" />
      <mass
        value="0.1" />
      <inertia
        ixx="0.00013604"
        ixy="-0.00000004"
        ixz="0.00000024"
        iyy="0.00013634"
        iyz="0.0000174"
        izz="0.00006903" />
    </inertial>
    <visual>
      <origin
        xyz="0 0 0"
        rpy="0 0 0" />
      <geometry>
        <mesh
          filename="package://Tele-arm-right.SLDASM/meshes/link1_Link.STL" />
      </geometry>
      <material
        name="">
        <color
          rgba="0.752941176470588 0.752941176470588 0.752941176470588 1" />
      </material>
    </visual>
    <collision>
      <origin
        xyz="0 0 0"
        rpy="0 0 0" />
      <geometry>
        <mesh
          filename="package://Tele-arm-right.SLDASM/meshes/link1_Link.STL" />
      </geometry>
    </collision>
  </link>
  <joint
    name="link1_Joint"
    type="revolute">
    <origin
      xyz="-0.00060482 0 0.13105"
      rpy="0 0 0" />
    <parent
      link="base_link" />
    <child
      link="link1_Link" />
    <axis
      xyz="0 0 1" />
    <limit
      lower="-1.57"
      upper="1.57"
      effort="3.5"
      velocity="12.566" />
  </joint>
  <link
    name="link2_Link">
    <inertial>
      <origin
        xyz="0.000220495029667861 0.0305499563819426 0.0525790783221891"
        rpy="0 0 0" />
      <mass
        value="0.8" />
      <inertia
        ixx="0.00276944"
        ixy="-0.00000202"
        ixz="0.00000245"
        iyy="0.00271631"
        iyz="-0.00005028"
        izz="0.0003914" />
    </inertial>
    <visual>
      <origin
        xyz="0 0 0"
        rpy="0 0 0" />
      <geometry>
        <mesh
          filename="package://Tele-arm-right.SLDASM/meshes/link2_Link.STL" />
      </geometry>
      <material
        name="">
        <color
          rgba="0.752941176470588 0.752941176470588 0.752941176470588 1" />
      </material>
    </visual>
    <collision>
      <origin
        xyz="0 0 0"
        rpy="0 0 0" />
      <geometry>
        <mesh
          filename="package://Tele-arm-right.SLDASM/meshes/link2_Link.STL" />
      </geometry>
    </collision>
  </link>
  <joint
    name="link2_Joint"
    type="revolute">
    <origin
      xyz="-2.36911467972752E-05 -0.0144929879654747 0.06"
      rpy="0 0 0" />
    <parent
      link="link1_Link" />
    <child
      link="link2_Link" />
    <axis
      xyz="0 1 0" />
    <limit
      lower="-1.22"
      upper="0.7"
      effort="9"
      velocity="3.77" />
  </joint>
  <link
    name="link3_Link">
    <inertial>
      <origin
        xyz="-0.064602664442897 0.00804230445951633 3.79087772330311E-05"
        rpy="0 0 0" />
      <mass
        value="0.29" />
      <inertia
        ixx="0.00012566"
        ixy="0.00004992"
        ixz="-0.00000012"
        iyy="0.00067872"
        iyz="0.00000003"
        izz="0.00068851" />
    </inertial>
    <visual>
      <origin
        xyz="0 0 0"
        rpy="0 0 0" />
      <geometry>
        <mesh
          filename="package://Tele-arm-right.SLDASM/meshes/link3_Link.STL" />
      </geometry>
      <material
        name="">
        <color
          rgba="0.752941176470588 0.752941176470588 0.752941176470588 1" />
      </material>
    </visual>
    <collision>
      <origin
        xyz="0 0 0"
        rpy="0 0 0" />
      <geometry>
        <mesh
          filename="package://Tele-arm-right.SLDASM/meshes/link3_Link.STL" />
      </geometry>
    </collision>
  </link>
  <joint
    name="link3_Joint"
    type="revolute">
    <origin
      xyz="0 0.00424999999999998 0.109999318004603"
      rpy="0 0 0" />
    <parent
      link="link2_Link" />
    <child
      link="link3_Link" />
    <axis
      xyz="0 1 0" />
    <limit
      lower="-0.79"
      upper="1.4"
      effort="3.5"
      velocity="12.566" />
  </joint>
  <link
    name="link4_Link">
    <inertial>
      <origin
        xyz="-0.107366094897431 -5.67609698076581E-05 -0.0796882625174483"
        rpy="0 0 0" />
      <mass
        value="0.33" />
      <inertia
        ixx="0.00044313"
        ixy="0.0000001"
        ixz="-0.00047514"
        iyy="0.00153976"
        iyz="0.00000019"
        izz="0.00121574" />
    </inertial>
    <visual>
      <origin
        xyz="0 0 0"
        rpy="0 0 0" />
      <geometry>
        <mesh
          filename="package://Tele-arm-right.SLDASM/meshes/link4_Link.STL" />
      </geometry>
      <material
        name="">
        <color
          rgba="0.752941176470588 0.752941176470588 0.752941176470588 1" />
      </material>
    </visual>
    <collision>
      <origin
        xyz="0 0 0"
        rpy="0 0 0" />
      <geometry>
        <mesh
          filename="package://Tele-arm-right.SLDASM/meshes/link4_Link.STL" />
      </geometry>
    </collision>
  </link>
  <joint
    name="link4_Joint"
    type="revolute">
    <origin
      xyz="-0.109992581095629 0.0102500000277369 0"
      rpy="0 0 0" />
    <parent
      link="link3_Link" />
    <child
      link="link4_Link" />
    <axis
      xyz="1 0 0" />
    <limit
      lower="-1.22"
      upper="4.36"
      effort="0.8"
      velocity="15.708" />
  </joint>
  <link
    name="link5_Link">
    <inertial>
      <origin
        xyz="-0.0241870109532369 -0.0891246644459004 0.0585775122227238"
        rpy="0 0 0" />
      <mass
        value="0.37" />
      <inertia
        ixx="0.00081321"
        ixy="-0.00011216"
        ixz="0.00012161"
        iyy="0.00049769"
        iyz="0.00027309"
        izz="0.00056826" />
    </inertial>
    <visual>
      <origin
        xyz="0 0 0"
        rpy="0 0 0" />
      <geometry>
        <mesh
          filename="package://Tele-arm-right.SLDASM/meshes/link5_Link.STL" />
      </geometry>
      <material
        name="">
        <color
          rgba="0.752941176470588 0.752941176470588 0.752941176470588 1" />
      </material>
    </visual>
    <collision>
      <origin
        xyz="0 0 0"
        rpy="0 0 0" />
      <geometry>
        <mesh
          filename="package://Tele-arm-right.SLDASM/meshes/link5_Link.STL" />
      </geometry>
    </collision>
  </link>
  <joint
    name="link5_Joint"
    type="revolute">
    <origin
      xyz="-0.14939 0 -0.07391"
      rpy="0 0 0" />
    <parent
      link="link4_Link" />
    <child
      link="link5_Link" />
    <axis
      xyz="-0.38268 0 0.92388" />
    <limit
      lower="-4.36"
      upper="1.22"
      effort="0.8"
      velocity="15.708" />
  </joint>
  <link
    name="link6_Link">
    <inertial>
      <origin
        xyz="0.0213206434718717 0.131792728574596 -0.000874059653897391"
        rpy="0 0 0" />
      <mass
        value="0.315" />
      <inertia
        ixx="0.00129383"
        ixy="-0.00026276"
        ixz="-0.0000248"
        iyy="0.00021009"
        iyz="-0.00009086"
        izz="0.00134004" />
    </inertial>
    <visual>
      <origin
        xyz="0 0 0"
        rpy="0 0 0" />
      <geometry>
        <mesh
          filename="package://Tele-arm-right.SLDASM/meshes/link6_Link.STL" />
      </geometry>
      <material
        name="">
        <color
          rgba="0.752941176470588 0.752941176470588 0.752941176470588 1" />
      </material>
    </visual>
    <collision>
      <origin
        xyz="0 0 0"
        rpy="0 0 0" />
      <geometry>
        <mesh
          filename="package://Tele-arm-right.SLDASM/meshes/link6_Link.STL" />
      </geometry>
    </collision>
  </link>
  <joint
    name="link6_Joint"
    type="revolute">
    <origin
      xyz="-0.030615 -0.08 0.07391"
      rpy="0 0 0" />
    <parent
      link="link5_Link" />
    <child
      link="link6_Link" />
    <axis
      xyz="0 1 0" />
    <limit
      lower="-1.61"
      upper="3.97"
      effort="0.8"
      velocity="15.708" />
  </joint>
  <link
    name="gripper_Link">
    <inertial>
      <origin
        xyz="0.0101676700398327 -0.00964993358196982 0.0435072746373087"
        rpy="0 0 0" />
      <mass
        value="0.015" />
      <inertia
        ixx="0.00000053"
        ixy="0.00000021"
        ixz="0.00000014"
        iyy="0.00000042"
        iyz="-0.00000019"
        izz="0.0000006" />
    </inertial>
    <visual>
      <origin
        xyz="0 0 0"
        rpy="0 0 0" />
      <geometry>
        <mesh
          filename="package://Tele-arm-right.SLDASM/meshes/gripper_Link.STL" />
      </geometry>
      <material
        name="">
        <color
          rgba="0.752941176470588 0.752941176470588 0.752941176470588 1" />
      </material>
    </visual>
    <collision>
      <origin
        xyz="0 0 0"
        rpy="0 0 0" />
      <geometry>
        <mesh
          filename="package://Tele-arm-right.SLDASM/meshes/gripper_Link.STL" />
      </geometry>
    </collision>
  </link>
  <joint
    name="gripper_Joint"
    type="revolute">
    <origin
      xyz="0.032764 0.16888 -0.031841"
      rpy="0 0 0" />
    <parent
      link="link6_Link" />
    <child
      link="gripper_Link" />
    <axis
      xyz="0 0 1" />
    <limit
      lower="-0.63"
      upper="0"
      effort="0.8"
      velocity="15.708" />
  </joint>
  <link
    name="force_Link">
    <inertial>
      <origin
        xyz="-1.41077149962143E-11 0.0799999999999982 -3.84194898117585E-11"
        rpy="0 0 0" />
      <mass
        value="0.0001135" />
      <inertia
        ixx="4.72916666666668E-10"
        ixy="-2.31488822181412E-26"
        ixz="7.41677518472587E-27"
        iyy="4.72916666666668E-10"
        iyz="2.08959431077767E-26"
        izz="4.72916666666668E-10" />
    </inertial>
    <visual>
      <origin
        xyz="0 0 0"
        rpy="0 0 0" />
      <geometry>
        <mesh
          filename="package://Tele-arm-right.SLDASM/meshes/force_Link.STL" />
      </geometry>
      <material
        name="">
        <color
          rgba="0.698039215686274 0.698039215686274 0.698039215686274 1" />
      </material>
    </visual>
    <collision>
      <origin
        xyz="0 0 0"
        rpy="0 0 0" />
      <geometry>
        <mesh
          filename="package://Tele-arm-right.SLDASM/meshes/force_Link.STL" />
      </geometry>
    </collision>
  </link>
  <joint
    name="force_Joint"
    type="fixed">
    <origin
      xyz="0 0 0"
      rpy="0 0 0" />
    <parent
      link="link6_Link" />
    <child
      link="force_Link" />
    <axis
      xyz="0 0 0" />
  </joint>
</robot>